Workbook

Sheet Document Title
B5: TM Forum Guidebook
B7: Core Network Deployment Questionnaire
B9: This document provides details of the TM Forum Autonomous Networks Questionaires in Excel format.
B16: GB1522B
B20: Maturity Level: Alpha | C20: Team Approved Date: 23-Jan-2026
B21: Release Status: Pre-production | C21: Approval Status: Team Approved
B22: Version 1.0.0 | C22: IPR Mode: RAND
B25: ãTM Forum 2026. All Rights Reserved.

Sheet Legal Notice
A6: Notice
A7: Copyright © TM Forum 2026. All Rights Reserved.
A9: This document and translations of it may be copied and furnished to others, and derivative works that comment on or otherwise explain it or assist in its implementation may be prepared, copied, published, and distributed, in whole or in part, without restriction of any kind, provided that the above copyright notice and this section are included on all such copies and derivative works. However, this document itself may not be modified in any way, including by removing the copyright notice or references to TM FORUM, except as needed for the purpose of developing any document or deliverable produced by a TM FORUM Collaboration Project Team (in which case the rules applicable to copyrights, as set forth in the TM FORUM IPR Policy must be followed) or as required to translate it into languages other than English.
A10: The limited permissions granted above are perpetual and will not be revoked by TM FORUM or its successors or assigns.
A12: This document and the information contained herein is provided on an "AS IS" basis and TM FORUM DISCLAIMS ALL WARRANTIES, EXPRESS OR IMPLIED, INCLUDING BUT NOT LIMITED TO ANY WARRANTY THAT THE USE OF THE INFORMATION HEREIN WILL NOT INFRINGE ANY OWNERSHIP RIGHTS OR ANY IMPLIED WARRANTIES OF MERCHANTABILITY OR FITNESS FOR A PARTICULAR PURPOSE.
A14: Direct inquiries to the TM Forum office:
A15: 100 Enterprise Drive Suite 304, #1649 Rockaway, NJ 07866 USA Tel No. +1 862 227 1648 TM Forum Web Page: www.tmforum.org
A27: ©TM Forum 2026. All Rights Reserved.

Sheet Guideline
B2: I. Introduction
B3: The scope of this questionnaire is to assess the autonomy of Network Functions Deployment, applicable for Core network domain
B4: The assessment is process-based and intended to be vendor and technology agnostic
B5: Dynamically Programable Rules: implies that the system uses rules that can be adjusted or modified in real-time based on changing conditions or requirements
B6: The questionnaire is based on the principles described in 3GPP TS 28.100 & IG1252
B7: It is recommended to have the participation of relevant SMEs to complete the assessment (Experts from Design and Deployment teams as well as automation experts)
B8: Each question is answered by selecting one of four options, A-D, option A being the highest level of autonomy and option D being the lowest
B9: Options A to D: They adopt a common approach reflecting S, P/S & P. They cover increasing levels of autonomy characteristics across the Options. Therefore, they should not include any reference to KEI/System accuracy
B10: More detailed guidelines per question are provided in the guideline section below
B12: II. Sub-scenarios Network Functions - Core
B13: Only 1 sub-scenario was considered for now. More sub-scenarios will be included based on further testing and feedback from mobile operators
B14: 1. Private Cloud 5GC with Full CNF Stack: This sub-scenario supports deployment of Network Functions for Enterprise-grade 5G with strict SLA
C18: III. Guideline for Answering ANL questionnaire
B19: Cognitive Activity (IAADE) | C19: Service Capability | D19: Question | E19: Answering Guideline
B20: Intent | C20: =Questionnaire!C4 -> Intent Translation & Fulfilment | D20: How does the System support the translation of Intents into Design & Deployment related policies and evaluates the Fulfillment of intent. e.g. the tasks of evaluating Network Function deployment fulfilment information (e.g. satisfied or not). | E20: "The role of intent in autonomous networks is to communicate requirements, goals, constraints, and preferences to an autonomous system. This knowledge enables the system to evaluate the state of the controlled infrastructure and the utility of actions. It enables a level of autonomy where the system can adapt its behavior and generate new solutions instead of just following human-defined recipes and policies." IG 1253 Intent in autonomous networks
E21: (A) The System automatically generates Design & Deployment (e.g. Network Function, date & time) policy actions based on Deployment intent, entered/updated by a Person. The System evaluates intent fulfillment based on implementation results.
E22: (B) Design & Deployment Intent is processed based on pre-defined rules, guided by a Person. Intent fulfilment is verified by a Person.
E23: (C) Design & Deployment Intent is processed using templates and guided workflows. Intent fulfillment is verified by a person.
E24: (D) Intent configuration and evaluation are entirely manually entered and confirmed based on human expertise.
B25: Awareness | C25: =Questionnaire!C5 -> Data collection | D25: How does the System support data collection and translates it to inputs to a specific integrated network delivery plan? | E25: (A) The collection of input data is automatically collected by the system and requires no human intervention to collect Design schemas and other data .
D26: Note: LLD design schema, network delivery plan, network element initialization data, network element parameter data (interface, IP, protocol, etc.) | E26: (B) Some level of regular manual intervention to the system is required to collect data
D27: and link it to deployment date and time, as defined in the Intent. | E27: (C) Commands or other input to the system is required each time data is collected
D28: Collected data should include data from external system(s), e.g., the NFVI resources available to deploy the new NF instance(s), data related to e.g. RAN, transport network. The Core Network management system may have to contact other management system(s) and ask for such data.
B29: Analysis | C29: =Questionnaire!C6 -> Data analysis | D29: How does the System support data analysis of inputs to a specific integrated network delivery plan to ensure data completeness and readiness? | E29: (A) AI based model correlates & validates multiple data sources automatically, to validate all required data is present
D30: e.g.: network resource, such as IP address, port, and backup resource availability … | E30: (B) Dynamically Programmable Rules/ML model correlates & validates multiple data sources automatically, to validate all required data is present
E31: (C) Run Book Automation is present to correlates & validates multiple data sources automatically, to validate all required data is present
E32: (D) Manual correlation of multiple data sources
C33: =Questionnaire!C7 -> Virtualized resource Feasibility check analysis | D33: How does the System support feasibility check analysis to verify there is enough available virtualized resource for the Network Function? | E33: (A) AI based models are able to run checks over the Inventory and in parallel to the systems by interrogating it with no human intervention and its able to adjust in case its found differences between Inventory data and Live system Data without Human intervention
E34: (B) Dynamically Programmable Rules/ML models are able to run checks over the Inventory and in parallel to the systems by interrogating it with no human intervention and its able to adjust in case its found differences between Inventory data and Live system Data and may require Human validation
E35: (C) Checks are done via Run Book Automations requires further Human validation
E36: (D) Feasibility check analysis is performed fully manually based on human expertise
C37: =Questionnaire!C7 -> Virtualized resource Feasibility check analysis | D37: How does the System support the generation of the specific integrated network delivery plan to deploy the Network Function, including the analysis of best deployment time? | E37: (A) Solution generation is performed by the system using AI Models without manual assistance or intervention
D38: (e.g. ensure the configuration and network connection, including Network Function configuration and transport network configuration are correct). | E38: (B) Solution generation is performed by the system using Dynamically Programmable Rules/ML models without manual assistance and may require human to validate the outcomes
E39: (C) Some solution options are generated by the system and additional solution options are generated by a person
E40: (D) All solution options are generated by a person
B41: Decision | C41: =Questionnaire!C9 -> Evaluation & decision-making | D41: How does the System support the evaluation & decision-making of the specific integrated network delivery plan and Network Function (e.g. parameters configuration data & virtualized resource information) ? | E41: (A) The system evaluates and decides the solution to be implemented using AI Models (may be only one possible solution in some cases, but its the optimal)
E42: (B) The system evaluates and decides the solution to be implemented using Dynamically Programmable Rules/ML Models and mare require human validation in case of multiple options/solutions are targeted
E43: (C) Human-guided Automation: a person selects and/or approves the solution to be implemented in the execution task
E44: (D) Fully manual evaluation and decision-making by a person
B45: Execution | C45: =Questionnaire!C10 -> Deployment | D45: How does the System support the deployment of specific Network Function ? | E45: (A) The System automatically executes deployment, without human intervention
...

Sheet Questionnaire
A1: High-Value Scenario | B1: Cognitive Activity (IAADE) | C1: Service Capability | D1: Weight | E1: Question | F1: Option A | G1: Option B | H1: Option C | I1: Option D | J1: Sub-scenarios Network Function Deployment - Core | L1: Interpretating on question | M1: Understanding of selecting the option
J2: Private Cloud 5GC with Full CNF Stack | K2: Other NF Core sub-scenario
J3: 0.8 | K3: 0.2
A4: Network Function Deployment - Core | B4: Intent | C4: Intent Translation & Fulfilment | D4: 0.1 | E4: How does the System support the translation of Intents into Design & Deployment related policies and evaluates the Fulfillment of intent. e.g. the tasks of evaluating Network Function deployment fulfilment information (e.g. satisfied or not). | F4: The System automatically generates Design & Deployment (e.g. Network Function, date & time) policy actions based on Deployment intent, entered/updated by a Person. The System evaluates intent fulfillment based on implementation results. | G4: Design & Deployment Intent is processed based on pre-defined rules, guided by a Person. Intent fulfilment is verified by a Person. | H4: Design & Deployment Intent is processed using templates and guided workflows. Intent fulfillment is verified by a person. | I4: Intent configuration and evaluation are entirely manually entered and confirmed based on human expertise. | J4: A | K4: A
B5: Awareness | C5: Data collection | D5: 0.1 | E5: How does the System support data collection and translates it to inputs to a specific integrated network delivery plan? Note: LLD design schema, network delivery plan, network element initialization data, network element parameter data (interface, IP, protocol, etc.) | F5: The System automatically collects data and translates it into inputs to a specific network delivery plan, without human intervention. | G5: The System automatically collects data and translates it into inputs to a specific network delivery plan, based on manually defined rules. | H5: Data is manually collected and translated it into input for a specific network delivery plan, based on human expertise | J5: A | K5: A
B6: Analysis | C6: Data analysis | D6: 0.15 | E6: How does the System support data analysis of inputs to a specific integrated network delivery plan to ensure data completeness and readiness? e.g.: network resource, such as IP address, port, and backup resource availability … | F6: The System analyses the data to ensure completeness and readiness, using AI Models, without human intervention. | G6: The System analyses the data to ensure completeness and readiness using Dynamically Programmable Rules or ML and may require Human validation. | H6: The System analyses the data to ensure completeness and readiness, based on pre-defined rules. | I6: Data analysis to ensure completeness is performed based on human expertise | J6: A | K6: A
C7: Virtualized resource Feasibility check analysis | D7: 0.15 | E7: How does the System support feasibility check analysis to verify there is enough available virtualized resource for the Network Function? | F7: The System performs feasibility check analysis using AI Models, without human intervention. | G7: The System performs feasibility check analysis using Dynamically Programmable Rules or ML and may require Human validation. | H7: The System performs feasibility check analysis, based on pre-defined rules | I7: Feasibility check analysis is performed based on human expertise | J7: A | K7: A
C8: Potential Solutions Deployment Generation | D8: 0.1 | E8: How does the System support the generation of the specific integrated network delivery plan to deploy the Network Function, including the analysis of best deployment time? (e.g. ensure the configuration and network connection, including Network Function configuration and transport network configuration are correct). | F8: The System generates the specific integrated network delivery plan using AI Models, without human intervention | G8: The System generates the specific integrated network delivery plan using Dynamically Programmable Rules or ML, and may require Human confirmation | H8: The System generates the specific integrated network delivery plan, based on pre-defined rules | I8: The generation of the specific integrated network delivery plan is based on human expertise | J8: A | K8: A
B9: Decision | C9: Evaluation & decision-making | D9: 0.15 | E9: How does the System support the evaluation & decision-making of the specific integrated network delivery plan and Network Function (e.g. parameters configuration data & virtualized resource information) including the best deployment time? | F9: The System evaluates and decides on the specific integrated network delivery plan to be deployed using AI Models, without human intervention | G9: The System automatically evaluates and decides on the specific integrated network delivery plan to be deployed using Dynamically Programmable Rules or ML, and may require Human confirmation | H9: The System evaluates and decides on the specific integrated network delivery plan to be deployed based on predefined rules | I9: The evaluation and decision making on the specific integrated network delivery plan to be deployed is based on human expertise | J9: A | K9: A
B10: Execution | C10: Deployment | D10: 0.15 | E10: How does the System support the deployment of specific Network Function ? (e.g.: deploying the Network Function based on determined VNF package and configuring the Network Function based on determined data). | F10: The System automatically executes deployment, without human intervention | G10: Human uses the System to execute deployment instructions remotely. | H10: Deployment of new network elements is done manually | J10: A | K10: A
C11: Implementation Verification | D11: 0.1 | E11: How does the System verify and confirm the implementation results? | F11: The System automatically verifies Network Function Deployment status and implementation results, without Human intervention | G11: The System verifies Network Function Deployment status and implementation results using Dynamically Programmable Rules or ML rules and may require Human confirmation | H11: The System verifies Network Function Deployment status and implementation results using pre-defined rules | I11: Verification of Network Function Deployment status and implementation results is performed entirely by human | J11: A | K11: A
D12: 1
A13: Note: 1) The questionnaire is intended for pilot use and will serve as input for future standardization efforts. 2) It is subject to change as the pilot progresses.

Sheet Scoring
A1: High-Value Scenario | B1: Cognitive Activity (IAADE) | C1: Service Capability | D1: Weight | E1: Question | F1: Scoring Method : Average | R1: Overal Score
F2: Sub-scenarios Core Network Deployment | L2: =J3 -> Private Cloud 5GC with Full CNF Stack | O2: =K3 -> Other NF Core sub-scenario
F3: Option A | G3: Option B | H3: Option C | I3: Option D | J3: =Questionnaire!J2 -> Private Cloud 5GC with Full CNF Stack | K3: =Questionnaire!K2 -> Other NF Core sub-scenario | L3: =Questionnaire!J3 -> 0.8 | O3: =Questionnaire!K3 -> 0.2
L4: Original score | M4: Compensated score | N4: Sub-score | O4: Original score | P4: Compensated score | Q4: Sub-score
A5: Network Function Deployment- Core | B5: Intent | C5: Intent Translation & Fulfilment | D5: 0.1 | E5: How does the System support the translation of Intents into Design & Deployment related policies and evaluates the Fulfillment of intent. e.g. the tasks of evaluating Network Function deployment fulfilment information (e.g. satisfied or not). | F5: 4 | G5: 3 | H5: 2 | I5: 1 | J5: =Questionnaire!J4 -> A | K5: =Questionnaire!K4 -> A | L5: =IF(J5="A",F5,IF(J5="B",G5, IF(J5="C",H5, IF(J5="D",I5)))) -> 4 | M5: =L5 -> 4 | N5: =SUMPRODUCT(M5:M12,D5:D12) -> 4 | O5: =IF(K5="A",F5,IF(K5="B",G5, IF(K5="C",H5, IF(K5="D",I5)))) -> 4 | P5: =O5 -> 4 | Q5: =SUMPRODUCT(P5:P12,D5:D12) -> 4 | R5: =(L3*N5+O3*Q5)/(L3+O3) -> 4
B6: Awareness | C6: Data collection | D6: 0.1 | E6: How does the System support data collection and translates it to inputs to a specific integrated network delivery plan? Note: LLD design schema, network delivery plan, network element initialization data, network element parameter data (interface, IP, protocol, etc.) | F6: 3 | G6: 2 | H6: 1 | I6: 0 | J6: =Questionnaire!J5 -> A | K6: =Questionnaire!K5 -> A | L6: =IF(J6="A",F6,IF(J6="B",G6, IF(J6="C",H6, IF(J6="D",I6)))) -> 3 | M6: =IF(AND(L6=3,AVERAGE(L5,L7,L8,L9,L10,L12)>3),AVERAGE(L5,L7,L8,L9,L10,L12),L6) -> 4 | O6: =IF(K6="A",F6,IF(K6="B",G6, IF(K6="C",H6, IF(K6="D",I6)))) -> 3 | P6: =IF(AND(O6=3,AVERAGE(O5,O7,O8,O9,O10,O12)>3),AVERAGE(O5,O7,O8,O9,O10,O12),O6) -> 4
B7: Analysis | C7: Data analysis | D7: 0.15 | E7: How does the System support data analysis of inputs to a specific integrated network delivery plan to ensure data completeness and readiness? e.g.: network resource, such as IP address, port, and backup resource availability … | F7: 4 | G7: 3 | H7: 2 | I7: 1 | J7: =Questionnaire!J6 -> A | K7: =Questionnaire!K6 -> A | L7: =IF(J7="A",F7,IF(J7="B",G7, IF(J7="C",H7, IF(J7="D",I7)))) -> 4 | M7: =L7 -> 4 | O7: =IF(K7="A",F7,IF(K7="B",G7, IF(K7="C",H7, IF(K7="D",I7)))) -> 4 | P7: =O7 -> 4
C8: Virtualized resource Feasibility check analysis | D8: 0.15 | E8: How does the System support feasibility check analysis to verify there is enough available virtualized resource for the Network Function? | F8: 4 | G8: 3 | H8: 2 | I8: 1 | J8: =Questionnaire!J7 -> A | K8: =Questionnaire!K7 -> A | L8: =IF(J8="A",F8,IF(J8="B",G8, IF(J8="C",H8, IF(J8="D",I8)))) -> 4 | M8: =L8 -> 4 | O8: =IF(K8="A",F8,IF(K8="B",G8, IF(K8="C",H8, IF(K8="D",I8)))) -> 4 | P8: =O8 -> 4
C9: Potential Solutions Deployment Generation | D9: 0.1 | E9: How does the System support the generation of the specific integrated network delivery plan to deploy the Network Function, including the analysis of best deployment time?(e.g. ensure the configuration and network connection, including Network Function configuration and transport network configuration are correct). | F9: 4 | G9: 3 | H9: 2 | I9: 1 | J9: =Questionnaire!J8 -> A | K9: =Questionnaire!K8 -> A | L9: =IF(J9="A",F9,IF(J9="B",G9, IF(J9="C",H9, IF(J9="D",I9)))) -> 4 | M9: =L9 -> 4 | O9: =IF(K9="A",F9,IF(K9="B",G9, IF(K9="C",H9, IF(K9="D",I9)))) -> 4 | P9: =O9 -> 4
B10: Decision | C10: Evaluation & decision-making | D10: 0.15 | E10: How does the System support the evaluation & decision-making of the specific integrated network delivery plan and Network Function (e.g. parameters configuration data & virtualized resource information) ? | F10: 4 | G10: 3 | H10: 2 | I10: 1 | J10: =Questionnaire!J9 -> A | K10: =Questionnaire!K9 -> A | L10: =IF(J10="A",F10,IF(J10="B",G10, IF(J10="C",H10, IF(J10="D",I10)))) -> 4 | M10: =L10 -> 4 | O10: =IF(K10="A",F10,IF(K10="B",G10, IF(K10="C",H10, IF(K10="D",I10)))) -> 4 | P10: =O10 -> 4
B11: Execution | C11: Deployment | D11: 0.15 | E11: How does the System support the deployment of specific Network Function ? (e.g.: deploying the Network Function based on determined VNF package and configuring the Network Function based on determined data). | F11: 2 | G11: 1 | H11: 0 | I11: 0 | J11: =Questionnaire!J10 -> A | K11: =Questionnaire!K10 -> A | L11: =IF(J11="A",F11,IF(J11="B",G11, IF(J11="C",H11, IF(J11="D",I11)))) -> 2 | M11: =IF(AND(L11=2,AVERAGE(L5,L7,L8,L9,L10,L12)>3),AVERAGE(L5,L7,L8,L9,L10,L12),L11) -> 4 | O11: =IF(K11="A",F11,IF(K11="B",G11, IF(K11="C",H11, IF(K11="D",I11)))) -> 2 | P11: =IF(AND(O11=2,AVERAGE(O5,O7,O8,O9,O10,O12)>3),AVERAGE(O5,O7,O8,O9,O10,O12),O11) -> 4
C12: Implementation Verification | D12: 0.1 | E12: How does the System verify and confirm the implementation results? | F12: 4 | G12: 3 | H12: 2 | I12: 1 | J12: =Questionnaire!J11 -> A | K12: =Questionnaire!K11 -> A | L12: =IF(J12="A",F12,IF(J12="B",G12, IF(J12="C",H12, IF(J12="D",I12)))) -> 4 | M12: =L12 -> 4 | O12: =IF(K12="A",F12,IF(K12="B",G12, IF(K12="C",H12, IF(K12="D",I12)))) -> 4 | P12: =O12 -> 4
D13: 1
B14: Note: Automatic formula calculation. Do not modify it.

Sheet Acknowledgements
D5: Member | E5: Company | F5: Role*
D6: Kevin McDonnell | E6: Huawei | F6: Project Chair
D7: Pedro Garcia Parra | E7: Telefónica | F7: Project Co-Chair
D8: Fernando Camacho | E8: Huawei | F8: Project Co-Chair
D9: Dinis Diogo | E9: Ericsson | F9: Author
D10: Jorgen Holmstrom | E10: Ericsson | F10: Co-Author
D11: Tony Salim | E11: Ericsson | F11: Reviewer
D12: David Condon | E12: Ericsson | F12: Reviewer
D13: Asser EL NAHAS | E13: Orange Group | F13: Key Contributor
D14: Esa Vesterinen | E14: Detecon | F14: Key Contributor
D15: Jacek Hanusik | E15: Detecon | F15: Key Contributor
D16: Sam Keys-Toyer | E16: Ericsson | F16: Key Contributor
D19: *Selected from: Project Chair, Project Co-Chair, Author, Editor, Key Contributor, Additional Input, Reviewer
