Workbook

Sheet Introduction_Orange
A1: Introduction
A2: 1. The assessment is questionnaire-based and it is used to evaluate the Autonomous Networks (AN) level in the fault management scenarios in the Core Network domain. The questionnaire includes the core network stability part which is considered as basic requirements and preconditions for fault management in the AN domain.
A3: 2. It is recommended that you complete the questionnaire together with specific technology and management domain engineers (core network architects and field maintenance engineers (FMEs)) for the following tasks: a) Core network architects and network planning engineers are suggested to answer questions related to the core network high-stability scenarios. b) Core network maintenance engineers are suggested to answer questions related to fault management (including Detection, Analysis, Decision, and Execution). c) If option A or option B is selected, related evidence is also required, according to the guidance for each question.
A4: 3. The fault management questions are designed to evaluate the core network's automation capability from the perspectives of automation and intelligence. a) From the process perspective, the definition of option A in this questionnaire indicates that the assessed core network is considered as a highly autonomous domain, enabled by intelligent automation in 95% of fault management scenarios. b) The definition of option B in this questionnaire indicates that the assessed core network is considered as a conditionally autonomous domain, enabled by rule-based automation in fault management. c) The definition of option C in this questionnaire indicates that the assessed core network provides partial automation in fault management. d) The definition of option D in this questionnaire indicates that the assessed core network relies on manual operations for fault management.
A5: 4. The core network stability questions are designed to evaluate network stability, focusing on the assessment of network redundancy and the process for proactive recovery of communication services in the event of NE faults. a) From the process perspective, option A in the core network stability questionnaire indicates that the assessed network is designed and deployed to ensure that communication services remain uninterrupted in the event of multiple NE faults. b) From the process perspective, option B in the core network stability questionnaire indicates that the assessed network is designed and deployed to enable quick recovery of communication services in the event of multiple NE faults. c) From the process perspective, option C in the core network stability questionnaire indicates that the assessed network is designed and deployed to enable quick recovery of communication services in the event of a single NE fault. d) From the process perspective, option D in the core network stability questionnaire indicates that the assessed network is designed and deployed, with communication services recovered through manual analysis, decision-making, and execution.
A6: 5. It is recommended that the core network fault management be assessed in a multi-vendor environment. When the core network fault management is assessed in multiple vendor environment, the evidences related to the answer should indicate vendor information or anonymous info. Overall score can be aggregated in multiple vendor scenario.
A7: 6. The core network high stability process is considered as the foundation of the core network fault management process. Assuming a fault management score of A and a stability score of B, the final score = 50% * score A + 50% * score B. a) From the effectiveness perspective, a score of 4 or above in the core network fault management dimension should cover more than 95% of scenarios and achieve an accuracy of more than 90%. b) From the effectiveness perspective, a score of 3 or above in the core network high stability dimension should cover more than 90% of scenarios and achieve an accuracy of more than 90%.
A8: 7. The core network fault management questionnaire uses the average scoring method to calculate an overall score by aggregating the score of each question and its weight. Each scoring option for a question must satisfy all requirements before it can be selected. NOTE: An exception is permitted only when the assessed network/system does not meet the requirements specified in the option. For instance, the EPC NEs were not subject to the requirements applicable to 5GC NFs. Similarly, the assessed EPC or IMS NEs were not subject to the requirements applicable to 5GC NFs.
A9: 8. The intent task, an optional step in closed-loop management (see 3GPP TS 28.100 and TMF IG 1252), was not included in the core network fault management scenario. The questionnaire is intended to add the intent step according to the newest update in 3GPP specifications or other relevant industry references, when applicable.
A11: Change History
A12: Date | B12: Subject(s) | C12: Version
A13: 45385 | B13: Initial version: Core network fault management questionnaire for TMF AN evaluation pilot | C13: 0403
A14: 45503 | B14: Second version: - Separated fault management and planning (core network stability) into two questionnaires according to comments received in feedback (''Decouple assessment of the process from network architecture features''). - Updated the questions and corresponding option A from the process perspective, rather than listing the required capabilities and NE (see 'what we learned from the pilot'). - Updated the terminologies in data collection and correlation questions those are applicable to core network management according to the comments in FAQ of the confluence page. - Updated some vague wordings (e.g., Partially) describing specific technical issues according to comments received on the confluence page and comments in feedback ("Requirements to meet "Partial" are vague"). | C14: 0730
A15: 45541 | B15: - Update the scoring scheme when evaluate two questions. - Update the requirements in risk prediction and solution generation in fault management questionnaire. | C15: 0906

Sheet Document Title
B2: TM Forum Best Practice
B4: Individual Services Service Assurance Questionnaire
B6: This document provides details of the TM Forum Autonomous Networks Questionaires in Excel format.
B10: GB1503A
B14: Maturity Level: Beta | C14: Team Approved Date: 24-Jan-2026
B15: Release Status: Pre-production | C15: Approval Status: Team Approved
B16: Version 2.0.0 | C16: IPR Mode: RAND
B19: ãTM Forum 2025. All Rights Reserved.

Sheet Legal Notice
A2: Notice
A3: Copyright © TM Forum 2025. All Rights Reserved.
A5: This document and translations of it may be copied and furnished to others, and derivative works that comment on or otherwise explain it or assist in its implementation may be prepared, copied, published, and distributed, in whole or in part, without restriction of any kind, provided that the above copyright notice and this section are included on all such copies and derivative works. However, this document itself may not be modified in any way, including by removing the copyright notice or references to TM FORUM, except as needed for the purpose of developing any document or deliverable produced by a TM FORUM Collaboration Project Team (in which case the rules applicable to copyrights, as set forth in the TM FORUM IPR Policy, must be followed) or as required to translate it into languages other than English.
A7: The limited permissions granted above are perpetual and will not be revoked by TM FORUM or its successors or assigns.
A9: This document and the information contained herein is provided on an "AS IS" basis and TM FORUM DISCLAIMS ALL WARRANTIES, EXPRESS OR IMPLIED, INCLUDING BUT NOT LIMITED TO ANY WARRANTY THAT THE USE OF THE INFORMATION HEREIN WILL NOT INFRINGE ANY OWNERSHIP RIGHTS OR ANY IMPLIED WARRANTIES OF MERCHANTABILITY OR FITNESS FOR A PARTICULAR PURPOSE.
A11: Direct inquiries to the TM Forum office:
A13: 100 Enterprise Drive
A14: Suite 304, #1649
A15: Rockaway, NJ 07866 USA
A16: Tel No. +1 862 227 1648
A17: TM Forum Web Page: www.tmforum.org
A29: ©TM Forum 2025. All Rights Reserved.
A75: ãTM Forum 2022. All Rights Reserved.

Sheet Guideline
B2: I. Introduction
B3: The purpose of this questionnaire is to assess the autonomy level of Service Assurance High Value Scenarios. To be used for Individual Services - Service Assurance
B4: In the telecom industry, Service Assurance is about managing user experience, Anomaly, Problem and Performance Management. It involves continuous monitoring, management, and optimization to ensure Services meet defined quality levels, SLAs, and provide an optimal user experience.
B5: A Service is what CSPs offer for subscribers consumption. Subscribers can be a person, enterprise or machine. Examples of Services: Individual Services, Home Services and Enterprise Services
B6: The questionnaire assesses "In Life" Service and therefore, all underlying capabilities are assumed already in place
B7: The assessment is process-based and intended to be vendor-independent and where possible technology independent.
B8: Dynamic rules: implies that the system uses rules that can be adjusted or modified in real-time based on changing conditions or requirements
B9: The questionnaire is aligned with the principles described in 3GPP TS 28.100, IG1277, IG1252, IG1218 & eTOM
B10: The participation of relevant Subject Matter Experts is required to complete the assessment (1st and 2nd level operation engineers, Service Quality and automation experts)
B11: Each question is answered by selecting one of the four options: A, B, C or D. Option A being the highest level of autonomy and option D being the lowest
B12: Options A to D: They adopt a common approach reflecting S, P/S & P. They cover increasing levels of autonomy characteristics across the Options. Therefore, they should not include any reference to KEI/System accuracy
B13: More detailed guidelines per question are provided in the guideline section below
... B19: Experience: In this questionnaire, “Experience” refers to service experience indicators inferred from network and service data. It does not require specifically probe measurements. Example - Video quality, Gaming Experience, VoIP Quality and App level Experience [ Represent how the end user actually experiences the service]
C21: III. Guideline for Answering ANL Questionnaire
B22: Cognitive Activity (IAADE) | C22: Service Capability | D22: Question | E22: Answering Guideline
B23: Intent | C23: ='Service Assurance Questionnaire'!C4 -> Intent Translation & Fulfilment | D23: ='Service Assurance Questionnaire'!E4 -> How does the System translate Service intents (e.g., throughput, latency, availability) into network actions and evaluate their fulfillment? | E23: A) | F23: ='Service Assurance Questionnaire'!F4 -> The System automatically generates Service Assurance objectives (e.g., throughput targets, latency bounds) and policy actions based on Service intents, entered/updated by Person. The System evaluates and presents intent fulfillment based on implementation effect, and informs if intent is not fulfilled.
E24: B) | F24: ='Service Assurance Questionnaire'!F4 -> The System automatically generates Service Assurance objectives (e.g., throughput targets, latency bounds) and policy actions based on Service intents, entered/updated by Person. The System evaluates and presents intent fulfillment based on implementation effect, and informs if intent is not fulfilled.
E25: C) | F25: ='Service Assurance Questionnaire'!H4 -> The System processes Intent using templates and guided workflows. Intent fulfillment evaluation is manually validated.
E26: D) | F26: ='Service Assurance Questionnaire'!I4 -> Intent configuration and evaluation are entirely manual and based on human expertise.
B27: Awareness | C27: ='Service Assurance Questionnaire'!C5 -> Service Performance Monitoring & degradation/outage detection | D27: ='Service Assurance Questionnaire'!E5 -> How does the System monitor Service KPIs (e.g., throughput, latency, availability, experience KPIs, VoLTE/VoNR call drop rate) and detect performance degradation, outage or anomalies? | E27: A) | F27: ='Service Assurance Questionnaire'!F5 -> The System continuously monitors Service KPIs (e.g., throughput, latency, availability, experience KPIs, VoLTE/VoNR call drop rate) and detect performance degradation, outage or anomalies without human intervention.
E28: B) | F28: ='Service Assurance Questionnaire'!G5 -> The System continuously monitors Service KPIs (e.g., throughput, latency, availability, experience KPIs, VoLTE/VoNR call drop rate) and detect performance degradation, outage or anomalies based on predefined rules
E29: C) | F29: ='Service Assurance Questionnaire'!H5 -> Performance monitoring, Service degradation and anomaly / outage detection are determined based on human expertise
C30: ='Service Assurance Questionnaire'!C6 -> Service Performance degradation Prediction | D30: ='Service Assurance Questionnaire'!E6 -> How does the System predict Service degradation (e.g., throughput, latency, availability, experience KPIs, VoLTE/VoNR call drop rate) and SLA violation ? | E30: A) | F30: ='Service Assurance Questionnaire'!F6 -> The System uses self-learning AI Models to analyze Service KPIs (e.g., throughput, latency, availability, experience KPIs, VoLTE/VoNR call drop rate) and predicts SLA violations, without human intervention
E31: B) | F31: ='Service Assurance Questionnaire'!G6 -> The System uses dynamic rules (context-aware) or ML outputs to analyze Service KPIs (e.g., throughput, latency, availability, experience KPIs, VoLTE/VoNR call drop rate) and predicts SLA violations and may require human intervention (e.g. for model re-training)
E32: C) | F32: ='Service Assurance Questionnaire'!H6 -> The System predicts SLA violations based on pre-defined rules.
E33: D) | F33: ='Service Assurance Questionnaire'!I6 -> SLA violation is manually detected and addressed based on performance reports.
B34: Analysis | C34: ='Service Assurance Questionnaire'!C7 -> Service Degradation Impact Analysis | D34: ='Service Assurance Questionnaire'!E7 -> How does the System identify and analyze the impact of Service degradation (e.g., throughput, latency, stability issues, experience deterioration,VoLTE/VoNR call drop rate) on user experience or SLA compliance? | E34: A) | F34: ='Service Assurance Questionnaire'!F7 -> The System identifies and analyzes the impact of Service degradation (e.g., throughput, latency, stability issues, experience deterioration, VoLTE/VoNR call drop rate) using self-learning AI Models without human intervention.
E35: B) | F35: ='Service Assurance Questionnaire'!G7 -> The System identifies and analyzes the impact of Service degradation (e.g., throughput, latency, stability issues, experience deterioration, VoLTE/VoNR call drop rate) using dynamic rules (context-aware) or ML Outputs and may require human confirmation to proceed
E36: C) | F36: ='Service Assurance Questionnaire'!H7 -> The System identifies & analyzes impact of Service degradation, based on predefined rules
E37: D) | F37: ='Service Assurance Questionnaire'!I7 -> Impact of degradation is determined based on human expertise.
C38: ='Service Assurance Questionnaire'!C8 -> Service Degradation Demarcation & Root Cause Analysis | D38: ='Service Assurance Questionnaire'!E8 -> How does the System isolate the root causes of Service degradation by analyzing contributing factors within or across network domains (e.g., RAN, transport, core), covering performance, stability, and experience-related issues? | E38: A) | F38: ='Service Assurance Questionnaire'!F8 -> The System isolates and analyzes the root causes of Service degradation by evaluating contributing factors within or across network domains using self learning AI Models, without human intervention.
E39: B) | F39: ='Service Assurance Questionnaire'!G8 -> The System isolates and analyzes the root cause of Service degradation using Dynamic Rules (context-aware) or ML Outputs and may require human intervention
E40: C) | F40: ='Service Assurance Questionnaire'!H8 -> The System isolates & analyzes performance degradation Root Cause, based on predefined rules
E41: D) | F41: ='Service Assurance Questionnaire'!I8 -> Performance data and alarms are manually analyzed to determine the root cause.
C42: ='Service Assurance Questionnaire'!C9 -> Solution Generation | D42: ='Service Assurance Questionnaire'!E9 -> How does the System generate solutions to address Service degradation (performance, stability, or experience) based on root cause analysis? | E42: A) | F42: ='Service Assurance Questionnaire'!F9 -> The System generates corrective actions (towards specific user group, service type and Apps) to address Service degradation and continuously learns from past resolutions using AI Models, without human intervention.
E43: B) | F43: ='Service Assurance Questionnaire'!G9 -> The System generates corrective actions using dynamic rules (context-aware) or ML Outputs and may require human confirmation
E44: C) | F44: ='Service Assurance Questionnaire'!H9 -> The System suggests corrective actions based on pre-defined rules.
E45: D) | F45: ='Service Assurance Questionnaire'!I9 -> Solutions are manually created based on human expertise
F46: Past resolution means system learns/self adapts from previous actions/solutions.
B47: Decision | C47: ='Service Assurance Questionnaire'!C10 -> Solution Evaluation & Decision making | D47: ='Service Assurance Questionnaire'!E10 -> How does the System evaluate solutions and decide on the optimal solution to implement ? | E47: A) | F47: ='Service Assurance Questionnaire'!F10 -> The System evaluates multiple remediation options, analyzes risk and trade-offs, and selects the optimal solution using self learning AI Models, without requiring human decision-making.
...

Sheet Service Assurance Questionnaire
A1: Process Flow | B1: Cognitive Activity | C1: Service Capability | D1: Weight | E1: Questions | F1: Option A | G1: Option B | H1: Option C | I1: Option D | J1: Industry Standard Reference | K1: Sub-scenarios | N1: Understanding of Options | O1: Interpretation on Questions
K2: Anomaly & Stability | L2: Performance | M2: Experience
K3: 0.2 | L3: 0.4 | M3: 0.4
A4: Service Assurance | B4: Intent | C4: Intent Translation & Fulfilment | D4: 0.1 | E4: How does the System translate Service intents (e.g., throughput, latency, availability) into network actions and evaluate their fulfillment? | F4: The System automatically generates Service Assurance objectives (e.g., throughput targets, latency bounds) and policy actions based on Service intents, entered/updated by Person. The System evaluates and presents intent fulfillment based on implementation effect, and informs if intent is not fulfilled. | G4: The System processes Intent using predefined rules and policies. Intent fulfillment evaluation is manually validated. | H4: The System processes Intent using templates and guided workflows. Intent fulfillment evaluation is manually validated. | I4: Intent configuration and evaluation are entirely manual and based on human expertise. | J4: 3GPP TS 28.100 7.1.1 Intent handling: - Task A: control information generation and determination. - Task B: intent fulfilment evaluation. | K4: A | L4: A | M4: A
B5: Awareness | C5: Service Performance Monitoring & degradation/outage detection | D5: 0.1 | E5: How does the System monitor Service KPIs (e.g., throughput, latency, availability, experience KPIs, VoLTE/VoNR call drop rate) and detect performance degradation, outage or anomalies? | F5: The System continuously monitors Service KPIs (e.g., throughput, latency, availability, experience KPIs, VoLTE/VoNR call drop rate) and detect performance degradation, outage or anomalies without human intervention. | G5: The System continuously monitors Service KPIs (e.g., throughput, latency, availability, experience KPIs, VoLTE/VoNR call drop rate) and detect performance degradation, outage or anomalies based on predefined rules | H5: Performance monitoring, Service degradation and anomaly / outage detection are determined based on human expertise | J5: 3GPP TS 28.100 7.1.1 Awareness: - Task C: information collection. | K5: A | L5: A | M5: A
C6: Service Performance degradation Prediction | D6: 0.1 | E6: How does the System predict Service degradation (e.g., throughput, latency, availability, experience KPIs, VoLTE/VoNR call drop rate) and SLA violation ? | F6: The System uses self-learning AI Models to analyze Service KPIs (e.g., throughput, latency, availability, experience KPIs, VoLTE/VoNR call drop rate) and predicts SLA violations, without human intervention | G6: The System uses dynamic rules (context-aware) or ML outputs to analyze Service KPIs (e.g., throughput, latency, availability, experience KPIs, VoLTE/VoNR call drop rate) and predicts SLA violations and may require human intervention (e.g. for model re-training) | H6: The System predicts SLA violations based on pre-defined rules. | I6: SLA violation is manually detected and addressed based on performance reports. | J6: 3GPP TS 28.100 7.1.1 Analysis: - Task D: issues identification. - Task E: deterioration prediction. | K6: A | L6: A | M6: A
B7: Analysis | C7: Service Degradation Impact Analysis | D7: 0.1 | E7: How does the System identify and analyze the impact of Service degradation (e.g., throughput, latency, stability issues, experience deterioration,VoLTE/VoNR call drop rate) on user experience or SLA compliance? | F7: The System identifies and analyzes the impact of Service degradation (e.g., throughput, latency, stability issues, experience deterioration, VoLTE/VoNR call drop rate) using self-learning AI Models without human intervention. | G7: The System identifies and analyzes the impact of Service degradation (e.g., throughput, latency, stability issues, experience deterioration, VoLTE/VoNR call drop rate) using dynamic rules (context-aware) or ML Outputs and may require human confirmation to proceed | H7: The System identifies & analyzes impact of Service degradation, based on predefined rules | I7: Impact of degradation is determined based on human expertise. | J7: 3GPP TS 28.100 7.1.1 Analysis: - Task F: Network issue demarcation. The tasks of analyze the network issue and determine the network issue categories (e.g. weak coverage, high load, low throughput). - Task G: Network issue root cause analysis. The tasks of analyzing the root cause (i.e. the location for the issue occurs and the cause for the issue) of the identified or predicted network issues. | K7: A | L7: A | M7: A
C8: Service Degradation Demarcation & Root Cause Analysis | D8: 0.15 | E8: How does the System isolate the root causes of Service degradation by analyzing contributing factors within or across network domains (e.g., RAN, transport, core), covering performance, stability, and experience-related issues? | F8: The System isolates and analyzes the root causes of Service degradation by evaluating contributing factors within or across network domains using self learning AI Models, without human intervention. | G8: The System isolates and analyzes the root cause of Service degradation using Dynamic Rules (context-aware) or ML Outputs and may require human intervention | H8: The System isolates & analyzes performance degradation Root Cause, based on predefined rules | I8: Performance data and alarms are manually analyzed to determine the root cause. | J8: 3GPP TS 28.100 7.1.1 Analysis: - Task F: Network issue demarcation. The tasks of analyze the network issue and determine the network issue categories (e.g. weak coverage, high load, low throughput). - Task G: Network issue root cause analysis. The tasks of analyzing the root cause (i.e. the location for the issue occurs and the cause for the issue) of the identified or predicted network issues. | K8: A | L8: A | M8: A
C9: Solution Generation | D9: 0.15 | E9: How does the System generate solutions to address Service degradation (performance, stability, or experience) based on root cause analysis? | F9: The System generates corrective actions (towards specific user group, service type and Apps) to address Service degradation and continuously learns from past resolutions using AI Models, without human intervention. | G9: The System generates corrective actions using dynamic rules (context-aware) or ML Outputs and may require human confirmation | H9: The System suggests corrective actions based on pre-defined rules. | I9: Solutions are manually created based on human expertise | J9: 3GPP TS 28.100 7.1.1 Analysis: - Task H: solutions analysis. | K9: A | L9: A | M9: A
B10: Decision | C10: Solution Evaluation & Decision making | D10: 0.2 | E10: How does the System evaluate solutions and decide on the optimal solution to implement ? | F10: The System evaluates multiple remediation options, analyzes risk and trade-offs, and selects the optimal solution using self learning AI Models, without requiring human decision-making. | G10: The System evaluates remediation options, recommends the optimal solution to be executed using Dynamic rules (context-aware) or ML Outputs and may require human approval | H10: The System evaluates remediation options, recommends the optimal solution to be executed based on pre-defined rules. Option selection is made by Human | I10: Remediation options, risk assessment and selection of appropriate solutions are manually done | J10: 3GPP TS 28.100 7.1.1 Decision: - Task I: solutions evaluation and determination. | K10: A | L10: A | M10: A
B11: Execution | C11: Solution Implementation | D11: 0.1 | E11: How does the System implement solution and apply fallback mechanisms in case of solution failure? | F11: The System implements the selected corrective action and triggers fallback mechanisms in case of failure, without human intervention | G11: The System applies corrective action and fallback mechanisms using pre-defined rules, based on human approval. | H11: Implementation and fallback handling of the corrective action are manually executed | J11: 3GPP TS 28.100 7.1.1 Execution: - Task J: solutions execution. | K11: A | L11: A | M11: A
D12: =SUM(D4:D11) -> 1
A13: Note: (1) The questionnaire is intended for pilot use and will serve as the input for future standardization. (2) It is subject to changes as the pilot progresses.

Sheet Scoring
A1: Process Flow | B1: Cognitive Activity | C1: Service Capability | D1: Weight | E1: Question | F1: Method: Average
F2: Criteria | J2: Answer | M2: Anomaly & Stability | P2: Performance | S2: Experience | V2: Final Score
M3: 0.2 | P3: 0.4 | S3: 0.4
F4: Option A | G4: Option B | H4: Option C | I4: Option D | J4: Anomaly & Stability | K4: Performance | L4: Experience | M4: Original score | N4: Compensated score | O4: Overall Score | P4: Original score | Q4: Compensated score | R4: Overall Score | S4: Original score | T4: Compensated score | U4: Overall Score
A5: Service Assurance | B5: Intent | C5: ='Service Assurance Questionnaire'!C4 -> Intent Translation & Fulfilment | D5: ='Service Assurance Questionnaire'!D4 -> 0.1 | E5: ='Service Assurance Questionnaire'!E4 -> How does the System translate Service intents (e.g., throughput, latency, availability) into network actions and evaluate their fulfillment? | F5: 4 | G5: 3 | H5: 2 | I5: 1 | J5: ='Service Assurance Questionnaire'!K4 -> A | K5: ='Service Assurance Questionnaire'!L4 -> A | L5: ='Service Assurance Questionnaire'!M4 -> A | M5: =IF(J5="A",F5,IF(J5="B",G5, IF(J5="C",H5, IF(J5="D",I5)))) -> 4 | N5: =M5 -> 4 | O5: =SUMPRODUCT(N5:N12,D5:D12) -> 4 | P5: =IF(K5="A",F5,IF(K5="B",G5, IF(K5="C",H5, IF(K5="D",I5)))) -> 4 | Q5: =P5 -> 4 | R5: =SUMPRODUCT(Q5:Q12,D5:D12) -> 4 | S5: =IF(L5="A",F5,IF(L5="B",G5, IF(L5="C",H5, IF(L5="D",I5)))) -> 4 | T5: =S5 -> 4 | U5: =SUMPRODUCT(T5:T12,D5:D12) -> 4 | V5: =(O5*M3+R5*P3+U5*S3)/(M3+P3+S3) -> 4
B6: Awareness | C6: ='Service Assurance Questionnaire'!C5 -> Service Performance Monitoring & degradation/outage detection | D6: ='Service Assurance Questionnaire'!D5 -> 0.1 | E6: ='Service Assurance Questionnaire'!E5 -> How does the System monitor Service KPIs (e.g., throughput, latency, availability, experience KPIs, VoLTE/VoNR call drop rate) and detect performance degradation, outage or anomalies? | F6: 3 | G6: 2 | H6: 1 | I6: 0 | J6: ='Service Assurance Questionnaire'!K5 -> A | K6: ='Service Assurance Questionnaire'!L5 -> A | L6: ='Service Assurance Questionnaire'!M5 -> A | M6: =IF(J6="A",F6,IF(J6="B",G6, IF(J6="C",H6, IF(J6="D",I6)))) -> 3 | N6: =IF(AND(M6=3,AVERAGE(M$5,M$7,M$8,M$9,M$10,M$11)>3),AVERAGE(M$5,M$7,M$8,M$9,M$10,M$11),M6) -> 4 | P6: =IF(K6="A",F6,IF(K6="B",G6, IF(K6="C",H6, IF(K6="D",I6)))) -> 3 | Q6: =IF(AND(P6=3,AVERAGE(P$5,P$7,P$8,P$9,P$10,P$11)>3),AVERAGE(P$5,P$7,P$8,P$9,P$10,P$11),P6) -> 4 | S6: =IF(L6="A",F6,IF(L6="B",G6, IF(L6="C",H6, IF(L6="D",I6)))) -> 3 | T6: =IF(AND(S6=3,AVERAGE(S$5,S$7,S$8,S$9,S$10,S$11)>3),AVERAGE(S$5,S$7,S$8,S$9,S$10,S$11),S6) -> 4
C7: ='Service Assurance Questionnaire'!C6 -> Service Performance degradation Prediction | D7: ='Service Assurance Questionnaire'!D6 -> 0.1 | E7: ='Service Assurance Questionnaire'!E6 -> How does the System predict Service degradation (e.g., throughput, latency, availability, experience KPIs, VoLTE/VoNR call drop rate) and SLA violation ? | F7: 4 | G7: 3 | H7: 2 | I7: 1 | J7: ='Service Assurance Questionnaire'!K6 -> A | K7: ='Service Assurance Questionnaire'!L6 -> A | L7: ='Service Assurance Questionnaire'!M6 -> A | M7: =IF(J7="A",F7,IF(J7="B",G7, IF(J7="C",H7, IF(J7="D",I7)))) -> 4 | N7: =M7 -> 4 | P7: =IF(K7="A",F7,IF(K7="B",G7, IF(K7="C",H7, IF(K7="D",I7)))) -> 4 | Q7: =P7 -> 4 | S7: =IF(L7="A",F7,IF(L7="B",G7, IF(L7="C",H7, IF(L7="D",I7)))) -> 4 | T7: =S7 -> 4
B8: Analysis | C8: ='Service Assurance Questionnaire'!C7 -> Service Degradation Impact Analysis | D8: ='Service Assurance Questionnaire'!D7 -> 0.1 | E8: ='Service Assurance Questionnaire'!E7 -> How does the System identify and analyze the impact of Service degradation (e.g., throughput, latency, stability issues, experience deterioration,VoLTE/VoNR call drop rate) on user experience or SLA compliance? | F8: 4 | G8: 3 | H8: 2 | I8: 1 | J8: ='Service Assurance Questionnaire'!K7 -> A | K8: ='Service Assurance Questionnaire'!L7 -> A | L8: ='Service Assurance Questionnaire'!M7 -> A | M8: =IF(J8="A",F8,IF(J8="B",G8, IF(J8="C",H8, IF(J8="D",I8)))) -> 4 | N8: =M8 -> 4 | P8: =IF(K8="A",F8,IF(K8="B",G8, IF(K8="C",H8, IF(K8="D",I8)))) -> 4 | Q8: =P8 -> 4 | S8: =IF(L8="A",F8,IF(L8="B",G8, IF(L8="C",H8, IF(L8="D",I8)))) -> 4 | T8: =S8 -> 4
C9: ='Service Assurance Questionnaire'!C8 -> Service Degradation Demarcation & Root Cause Analysis | D9: ='Service Assurance Questionnaire'!D8 -> 0.15 | E9: ='Service Assurance Questionnaire'!E8 -> How does the System isolate the root causes of Service degradation by analyzing contributing factors within or across network domains (e.g., RAN, transport, core), covering performance, stability, and experience-related issues? | F9: 4 | G9: 3 | H9: 2 | I9: 1 | J9: ='Service Assurance Questionnaire'!K8 -> A | K9: ='Service Assurance Questionnaire'!L8 -> A | L9: ='Service Assurance Questionnaire'!M8 -> A | M9: =IF(J9="A",F9,IF(J9="B",G9, IF(J9="C",H9, IF(J9="D",I9)))) -> 4 | N9: =M9 -> 4 | P9: =IF(K9="A",F9,IF(K9="B",G9, IF(K9="C",H9, IF(K9="D",I9)))) -> 4 | Q9: =P9 -> 4 | S9: =IF(L9="A",F9,IF(L9="B",G9, IF(L9="C",H9, IF(L9="D",I9)))) -> 4 | T9: =S9 -> 4
C10: ='Service Assurance Questionnaire'!C9 -> Solution Generation | D10: ='Service Assurance Questionnaire'!D9 -> 0.15 | E10: ='Service Assurance Questionnaire'!E9 -> How does the System generate solutions to address Service degradation (performance, stability, or experience) based on root cause analysis? | F10: 4 | G10: 3 | H10: 2 | I10: 1 | J10: ='Service Assurance Questionnaire'!K9 -> A | K10: ='Service Assurance Questionnaire'!L9 -> A | L10: ='Service Assurance Questionnaire'!M9 -> A | M10: =IF(J10="A",F10,IF(J10="B",G10, IF(J10="C",H10, IF(J10="D",I10)))) -> 4 | N10: =M10 -> 4 | P10: =IF(K10="A",F10,IF(K10="B",G10, IF(K10="C",H10, IF(K10="D",I10)))) -> 4 | Q10: =P10 -> 4 | S10: =IF(L10="A",F10,IF(L10="B",G10, IF(L10="C",H10, IF(L10="D",I10)))) -> 4 | T10: =S10 -> 4
B11: Decision | C11: ='Service Assurance Questionnaire'!C10 -> Solution Evaluation & Decision making | D11: ='Service Assurance Questionnaire'!D10 -> 0.2 | E11: ='Service Assurance Questionnaire'!E10 -> How does the System evaluate solutions and decide on the optimal solution to implement ? | F11: 4 | G11: 3 | H11: 2 | I11: 1 | J11: ='Service Assurance Questionnaire'!K10 -> A | K11: ='Service Assurance Questionnaire'!L10 -> A | L11: ='Service Assurance Questionnaire'!M10 -> A | M11: =IF(J11="A",F11,IF(J11="B",G11, IF(J11="C",H11, IF(J11="D",I11)))) -> 4 | N11: =M11 -> 4 | P11: =IF(K11="A",F11,IF(K11="B",G11, IF(K11="C",H11, IF(K11="D",I11)))) -> 4 | Q11: =P11 -> 4 | S11: =IF(L11="A",F11,IF(L11="B",G11, IF(L11="C",H11, IF(L11="D",I11)))) -> 4 | T11: =S11 -> 4
B12: Execution | C12: ='Service Assurance Questionnaire'!C11 -> Solution Implementation | D12: ='Service Assurance Questionnaire'!D11 -> 0.1 | E12: ='Service Assurance Questionnaire'!E11 -> How does the System implement solution and apply fallback mechanisms in case of solution failure? | F12: 2 | G12: 1 | H12: 0 | I12: 0 | J12: ='Service Assurance Questionnaire'!K11 -> A | K12: ='Service Assurance Questionnaire'!L11 -> A | L12: ='Service Assurance Questionnaire'!M11 -> A | M12: =IF(J12="A",F12,IF(J12="B",G12, IF(J12="C",H12, IF(J12="D",I12)))) -> 2 | N12: =IF(AND(M12=2,AVERAGE(M$5,M$7,M$8,M$9,M$10,M$11)>2),AVERAGE(M$5,M$7,M$8,M$9,M$10,M$11),M12) -> 4 | P12: =IF(K12="A",F12,IF(K12="B",G12, IF(K12="C",H12, IF(K12="D",I12)))) -> 2 | Q12: =IF(AND(P12=2,AVERAGE(P$5,P$7,P$8,P$9,P$10,P$11)>2),AVERAGE(P$5,P$7,P$8,P$9,P$10,P$11),P12) -> 4 | S12: =IF(L12="A",F12,IF(L12="B",G12, IF(L12="C",H12, IF(L12="D",I12)))) -> 2 | T12: =IF(AND(S12=2,AVERAGE(S$5,S$7,S$8,S$9,S$10,S$11)>2),AVERAGE(S$5,S$7,S$8,S$9,S$10,S$11),S12) -> 4
B13: Note 1: Scores are automatically calculated by formulas, which cannot be changed.
D14: =SUM(D5:D12) -> 1

Sheet Acknowledgements
D5: Member | E5: Company | F5: Role*
D6: Kevin McDonnell | E6: Huawei | F6: Project Chair
D7: Pedro Garcia Parra | E7: Telefónica | F7: Project Co-Chair
D8: Fernando Camacho | E8: Huawei | F8: Project Co-Chair
D9: Saeed Mohamed | E9: Ericsson | F9: Author
D10: Tony Salim | E10: Ericsson | F10: Co-Author
D11: Luqman Shantal | E11: Makman Technology Consulting | F11: Key Contributor
D12: Menno Groen | E12: KPN | F12: Key Contributor
D13: Jörgen Holmström | E13: Ericsson | F13: Key Contributor
D14: David Condon | E14: Ericsson | F14: Reviewer
D15: Minjong Kim | E15: LG Uplus | F15: Reviewer
D16: Asser El Nahass | E16: Orange | F16: Reviewer
... D23: Jacek Hanusik | E23: Detecon | F23: Reviewer
D25: *Selected from: Project Chair, Project Co-Chair, Author, Editor, Key Contributor, Additional Input, Reviewer

Sheet Core Network Fault Management_O
A1: Scenarios | B1: Category | C1: Capability or Task | D1: Weight (Optional) | E1: Questions | F1: Option A | G1: Option B | H1: Option C | I1: Option D | J1: Industry Standard Reference | K1: Option A | L1: Option B | M1: Option C | N1: Option D | O1: Answer | P1: Interpretation on Questions | Q1: Understanding of Options
A2: Core network fault management - maintenance | B2: Intent | C2: Intent | D2: 0 | E2: n/a | F2: n/a | G2: n/a | H2: n/a | I2: n/a
B3: Awareness | C3: Data collection Alarm correlation | D3: 0.1 | E3: Does your system automatically collect data? Assessment object: the core network management function Core network NEs or NFs for assessment: core network NEs (e.g., 5GC NFs, EPC NEs, and IMS NEs) | F3: Yes. The system can automatically collect data (alarms, configuration data, and performance data etc.) and sort alarms. The data should be at the module level, including NF modules, cloud OS (VMs or pods), hardware (hosts and ports), detected KPIs indicating slight service damage (e.g., service KPI deterioration < 5%) and infrastructure-layer hardware data (servers, storage devices, EOR/TOR devices and IP core). | G3: The system can automatically collect data (alarms, configuration data, and performance data), associate alarms, and sort alarms. The data should be at the NE level and cloud OS ((VMs or pods). | H3: No. The system supports manual data collection. | J3: 3GPP TS 28.100 - 7.3 Generic autonomous network level for fault management 3GPP TS 28.541 - Clause 5 5GC network resource models 3GPP TS 28.545 - Clause 6 Fault Supervision management services - Clause 8 Virtualized resource alarm correlation | K3: 3 | L3: 2 | M3: 1 | O3: A
B4: Analysis | C4: Fault identification | D4: 0.1 | E4: Does your system support fault identification and visualization related to the core network status? Assessment object: the core network management function Core network NEs or NFs for assessment: core network NEs (e.g., 5GC NFs, EPC NEs, and IMS NEs) NOTE 1: "Degraded" is an intermediate state indicating that the network functions are abnormal, but not completely faulty. The example causes of NF degradations include the following: Packet loss occurs on host NICs; packet loss occurs on TOR/EOR switches; faults occur on CPU and memory resources. NOTE 2: Fault identification is used to provide detected exception information related to the network and services based on multiple data sources. | F4: The system supports automatic fault detection and identification and alarm aggregation in fault scenarios based on multiple data sources (alarms, KPIs, heartbeat messages, and identified issues etc.). The system can compress the number of alarm notifications and provide the aggregated alarms. Fault management supports visualization of the following management capabilities in one view of NEs/NFs and the telecom cloud. 1. NE object (5GC NFs and EPC NEs) status (faulty or normal) visualization 2. NE health status (degraded and overloaded) visualization 3. Visualized status (faulty or normal) of VMs and pods in the telecom cloud 4. Information of telecom cloud infrastructure, including server (CPU, memory, NIC) information, storage information, storage controller/storage port information, vNIC information and rack information | G4: The system supports automatic fault detection and identification and alarm aggregation in fault scenarios based on alarms or KPIs. The system can identify and filter out redundant alarm notifications and related tickets based on pre-defined rules. Fault management supports visualization of the following management capabilities: 1. NE object (5GC NFs and EPC NEs) status (faulty or normal) visualization 2. NE health status (degraded and overloaded) visualization 3. Visualized status (faulty or normal) of VMs and pods in the telecom cloud | H4: No. The system supports manual fault detection based on the alarm notification and KPIs. | J4: 3GPP TS 28.100 - 7.3 Generic autonomous network level for fault management 3GPP TS 28.552 - Clause 5 Performance measurements for 5G network functions 3GPP TS 28.554 - Clause 6, end to end KPIs 3GPP TS 28.541 - Clause 5 5GC network resource models 3GPP TS 28.545 - Clause 6 Fault Supervision management services - Clause 8 Virtualized resource alarm correlation | K4: 3 | L4: 2 | M4: 1 | O4: A
C5: Risk prediction | D5: 0.1 | E5: Does your system automatically detect and prevent risks of NE faults? Assessment object: management entities Core network NEs or NFs for assessment: core network NEs (e.g., 5GC NFs, EPC NEs, and IMS NEs) | F5: Yes. The system can use intelligent risk identification to recognize potential faults and automatically prevent faults. It can: 1. Prevent potential risks and analyze the risks involving capacity, links, signaling storms, DR, and hardware. 2. Analyze the cause of risks and provide recommended actions automatically. | G5: The system can use automatic risk identification, which requires manual confirmation, to recognize potential faults and prevent faults. It can: 1. Prevent potential risks and analyze the risks involving capacity and links. | H5: The system can use risk identification to recognize potential faults and prevent faults by providing an automatic checklist which requires engineers to periodically confirm the potential risks in this checklist. It can: 1. Prevent potential risks and analyze the risks involving capacity. | I5: No. The system does not support risk prediction. | J5: 3GPP TS 28.100 - 7.3 Generic autonomous network level for fault management 3GPP TS 28.104 - Clause 8.4.3 MDA assisted fault management 3GPP TS 28.104 - SLS related predictions, - E2E latency analysis, - Network slice load analysis, - Control plane congestion analysis. | K5: 4 | L5: 3 | M5: 2 | N5: 1 | O5: A
C6: Demarcation | D6: 0.15 | E6: Does your system support automatic demarcation of core network faults? Assessment object: the core network management function Core network NEs or NFs for assessment: core network NEs (e.g., 5GC NFs, EPC NEs and IMS NEs) | F6: Yes. The intelligent system supports automatic fault demarcation without manual intervention (e.g., core network NEs and managed objects in telecom cloud) covering 95% or higher of live network faults. The average accuracy per month is above 90%. The system supports demarcation of following scenarios: 1. Horizontal demarcation for NEs in the core network domain 2. Demarcation between VNFs and vertical demarcation for the telecom cloud | G6: The system supports automatic fault demarcation covering 80% or higher of faults (only for the alarms after aggregation and alarms generated based on KPI monitoring). The average accuracy per month is above 90%. The system supports demarcation of following scenarios: 1. Horizontal demarcation for NEs in the core network domain 2. Demarcation between VNFs and vertical demarcation for the telecom cloud | H6: The system supports automatic fault demarcation and provides one or multiple analysis results to assist fault demarcation. | I6: No. The system does not support automatic fault demarcation. | J6: 3GPP TS 28.100 - 7.3 Generic autonomous network level for fault management 3GPP TS 28.104 - Clause 8.4.3 MDA assisted fault management | K6: 4 | L6: 3 | M6: 2 | N6: 1 | O6: A
C7: Locating | D7: 0.15 | E7: Does your system support automatic locating related to core network fault management? Assessment object: the core network management function and network function Core network NEs or NFs for assessment: core network NEs (e.g., 5GC NFs, EPC NEs, and IMS NEs) | F7: Yes. Intelligent fault diagnosis is capable of automatically providing precise locating (e.g., detailed causes of identified faults, including minimum units, software modules, and ports) of faults, covering 95% or higher of live network faults without human intervention. The average accuracy per month is above 90%. | G7: Automatic fault diagnosis is capable of providing root causes of faults, and providing precise fault locating, covering 80% or higher faults (only for the alarms after aggregation and alarms generated based on KPI monitoring). The average accuracy per month is above 90%. | H7: The system supports automatic fault locating and provides one or multiple analysis results to assist fault locating. | I7: No. The system does not support automatic fault locating. | J7: 3GPP TS 28.100 - 7.3 Generic autonomous network level for fault management 3GPP TS 28.104 - Clause 8.4.3 MDA assisted fault management | K7: 4 | L7: 3 | M7: 2 | N7: 1 | O7: A
B8: Decision | C8: Fault rectification solution generation | D8: 0.1 | E8: Does your system automatically generate the fault rectification solution? Assessment object: the core network management function Core network NEs or NFs for assessment: core network NEs (e.g., 5GC NFs, EPC NEs, and IMS NEs) | F8: Yes. The system can generate the optimal rectification solution (minimum impact scope and time). Fault rectification can cover but not be limited to the following scenarios: 1. Generating an NF fault rectification solution automatically 2. Generating a solution to recover slight service losses 3. Providing a DR solution in case of accidents or natural disasters 4. System can generate optimization to network for failure (e.g., signaling storm, service outage etc.) automatically. | G8: The system can generate a fault rectification solution (e.g., fault rectification scripts including operation objects and operation sequences). Fault rectification can cover the following scenarios: 1. Providing a DR solution in case of accidents or natural disasters. 2. System can generate optimization to network for failure (e.g., signaling storm, service outage etc.) automatically. | H8: The system can generate fault rectification recommendations based on specialized checklist, to determine the rectification operations and operation objects based on rectification decision rules (configuration). Fault rectification can cover the following scenarios: 1. Providing a DR solution in case of accidents or natural disasters | I8: No. The system supports fault rectification based on manual decisions. | J8: 3GPP TS 28.100 - 7.3 Generic autonomous network level for fault management 3GPP TS 28.104 - Clause 8.4.3 MDA assisted fault management 3GPP TS 28.104 - Clause 7.2.3.2 Service failure recovery | K8: 4 | L8: 3 | M8: 2 | N8: 1 | O8: A
C9: Solution pre-verification | D9: 0.1 | E9: Does your system support rectification solution evaluation and verification to support decisions in core network? NOTE: Fault rectification solution can be evaluated before implementation by being verified in a simulation or sandbox environment. Assessment object: the core network management function Core network NEs or NFs for assessment: core network NEs (e.g., 5GC NFs, EPC NEs, and IMS NEs) | F9: Yes. The system supports intelligent rectification solution evaluation for the core network to verify the feasibility of rectification solution and provides the visualization results of accuracy effect before implementation. The evaluation tasks can cover but not be limited to the following scenarios: 1. Solution feasibility check and configuration verification 2. Emulation or simulation of rectification solution based on network digital twin The system supports the decision. | G9: The system supports automatic rectification solution evaluation for core network, to verify the feasibility of rectification solution before implementation. The evaluation tasks can cover the following scenarios: 1. Solution feasibility check and configuration verification 2. DR rectification solution evaluation and verification The system supports the simulation results for manual decisions made for rectification solution. | H9: The system provides a checklist for manual evaluation to verify the feasibility of rectification solution before implementation. The checklist includes but is not limited to: 1. NF healthy status check 2. Influence of rectification solution | I9: No. The system verifies the rectification solution based on manual decisions. | J9: 3GPP TS 28.100 - 7.3 Generic autonomous network level for fault management 3GPP TS 28.532 - 5.1.6 Network slice feasibility check 3GPP TR 28.915 - 5.9 Use case 9: Configuration verification - 5.2 Use case 2: Signaling storm analysis | K9: 4 | L9: 3 | M9: 2 | N9: 1 | O9: A
B10: Execution | C10: Solution implementation | D10: 0.1 | E10: Does your system support automatic fault rectification? Assessment object: the core network management function and network element Core network NEs or NFs for assessment: core network NEs (e.g., 5GC NFs, EPC NEs, and IMS NEs). | F10: Yes. The system can support automatic fault rectification in all fault rectification scenarios. | G10: The system supports fault rectification after manual confirmation. | J10: 3GPP TS 28.100 - 7.3 Generic autonomous network level for fault management | K10: 2 | L10: 1 | O10: A
C11: Service verification | D11: 0.1 | E11: Does your system support automatic service verification after faults on core networks are rectified? Assessment object: the core network management function Core network NEs or NFs for assessment: core network NEs (e.g., 5GC NFs, EPC NEs, and IMS NEs) | F11: Yes. The system automatically verifies whether network services are recovered and faults are rectified successfully. | G11: The system automatically verifies that the alarms are cleared and KPI data is successfully recovered. | H11: No. The system does not support automatic service verification. | J11: 3GPP TS 28.100 - 7.3 Generic autonomous network level for fault management 3GPP TS 28.541 - Clause 5 5GC network resource models 3GPP TS 28.552 - Clause 5 Performance measurements for 5G network functions 3GPP TS 28.554 - Clause 6, end to end KPIs 3GPP TS 28.545 - Clause 6 Fault Supervision management services - Clause 8 Virtualized resource alarm correlation 3GPP TS 28.523 - Performance Management (PM) for mobile networks that include virtualized network functions | K11: 4 | L11: 3 | M11: 2 | N11: 1 | O11: A
A12: Note: (1) The questionnaire is intended for pilot use and will serve as the input for future standardization. (2) It is subject to changes as the pilot progresses.

Sheet Scoring-Fault Management_Orange
A1: High-Value Scenario | B1: Cognitive Activity (IAADE) | C1: Service Capability | D1: Weight | E1: Question | F1: Method 1: Average (official use) | N1: Method 2: Climbing (for reference only)
F2: Criteria | J2: Answer | K2: Calculate | N2: Criteria | S2: Answer | T2: Calculate
F3: Option A | G3: Option B | H3: Option C | I3: Option D | K3: Original score | L3: Compensated score | M3: Overall Score | N3: Level 0 | O3: Level 1 | P3: Level 2 | Q3: Level 3 | R3: Level 4 | T3: Meet Level1 Criteria? | U3: Meet Level2 Criteria? | V3: Meet Level3 Criteria? | W3: Meet Level4 Criteria? | X3: Level Base | Y3: Next Level Require | Z3: Meet Next Level Require | AA3: Level Extra | AB3: Overall Score
A4: Core Network - Fault Management | B4: Awareness | C4: Data collection Alarm correlation | D4: 0.1 | E4: Does your system automatically collect the data. Assessment object: core network management function Core network NE or NFs for assessment: core network NEs (e.g., 5GC NF, EPC NE and IMS NE) | F4: 3 | G4: 2 | H4: 1 | J4: ='Core Network Fault Management_O'!O3 -> A | K4: =IF(J4="A",F4,IF(J4="B",G4, IF(J4="C",H4, IF(J4="D",I4)))) -> 3 | L4: =IF(AND(K4=3,AVERAGE(K6:K10,K12:K12)>3),AVERAGE(K6:K10,K12:K12),K4) -> 4 | M4: =SUMPRODUCT(L4:L12,D4:D12) -> 4 | O4: C | P4: B | Q4: A | R4: A | S4: A | T4: =IF(S4<=O4,1,0) -> 1 | U4: =IF(S4<=P4,1,0) -> 1 | V4: =IF(S4<=Q4,1,0) -> 1 | W4: =IF(S4<=R4,1,0) -> 1 | X4: =IF(AVERAGE(W4:W12)=1,4,IF(AVERAGE(V4:V12)=1,3,IF(AVERAGE(U4:U12)=1,2,IF(AVERAGE(T4:T12)=1,1,0)))) -> 4 | Y4: {=_xlfn.SWITCH(X4, 0, IF(O4<N4,1,0),1, IF(P4<O4,1,0), 2, IF(Q4<P4,1,0), 3, IF(R4<Q4,1,0),4,0)} -> 0 | Z4: {=IF(Y4>0,_xlfn.SWITCH(X4,0,IF(S4<=O4,1,0), 1,IF(S4<=P4,1,0),2,IF(S4<=Q4,1,0),3,IF(S4<=R4,1,0)),0)} -> 0 | AA4: =IF(X4=4,0,SUMPRODUCT(Z4:Z12,D4:D12))/IF(SUMPRODUCT(Y4:Y12,D4:D12)=0,1,SUMPRODUCT(Y4:Y12,D4:D12)) -> 0 | AB4: =AA4+X4 -> 4
B5: Analysis | C5: Fault identification | D5: 0.1 | E5: Does your system support fault identification and visualization related to the core network status? Assessment object: core network management function Core network NE or NFs for assessment: core network NEs (e.g., 5GC NF, EPC NE and IMS NE) NOTE: Degraded is an intermediate state that the network functions are abnormal, but not completely faulty. The example causes of NF degradation are packet loss occurs on host NICs, packet loss occurs on TOR/EOR switches, abnormal CPU and memory resources. NOTE: Fault identification is intended to provide detected abnormal related to network and service degradation based on multiple data sources. | F5: 3 | G5: 2 | H5: 1 | J5: ='Core Network Fault Management_O'!O4 -> A | K5: =IF(J5="A",F5,IF(J5="B",G5, IF(J5="C",H5, IF(J5="D",I5)))) -> 3 | L5: =IF(AND(K5=3,AVERAGE(K6:K10,K12:K12)>3),AVERAGE(K6:K10,K12:K12),K5) -> 4 | O5: C | P5: B | Q5: A | R5: A | S5: =J5 -> A | T5: =IF(S5<=O5,1,0) -> 1 | U5: =IF(S5<=P5,1,0) -> 1 | V5: =IF(S5<=Q5,1,0) -> 1 | W5: =IF(S5<=R5,1,0) -> 1 | Y5: {=_xlfn.SWITCH(X4, 0, IF(O5<N5,1,0),1, IF(P5<O5,1,0), 2, IF(Q5<P5,1,0), 3, IF(R5<Q5,1,0),4,0)} -> 0 | Z5: {=IF(Y5>0,_xlfn.SWITCH(X4,0,IF(S5<=O5,1,0), 1,IF(S5<=P5,1,0),2,IF(S5<=Q5,1,0),3,IF(S5<=R5,1,0)),0)} -> 0
C6: Risk prediction | D6: 0.1 | E6: Does your system automatically detect and prevent the risks of network NE faults? Assessment object: management entity Core network NE or NFs for assessment: core network NEs (e.g., 5GC NF, EPC NE and IMS NE) | F6: 4 | G6: 3 | H6: 2 | I6: 1 | J6: ='Core Network Fault Management_O'!O5 -> A | K6: =IF(J6="A",F6,IF(J6="B",G6, IF(J6="C",H6, IF(J6="D",I6)))) -> 4 | L6: =K6 -> 4 | O6: D | P6: C | Q6: B | R6: A | S6: =J6 -> A | T6: =IF(S6<=O6,1,0) -> 1 | U6: =IF(S6<=P6,1,0) -> 1 | V6: =IF(S6<=Q6,1,0) -> 1 | W6: =IF(S6<=R6,1,0) -> 1 | Y6: {=_xlfn.SWITCH(X4, 0, IF(O6<N6,1,0),1, IF(P6<O6,1,0), 2, IF(Q6<P6,1,0), 3, IF(R6<Q6,1,0),4,0)} -> 0 | Z6: {=IF(Y6>0,_xlfn.SWITCH(X4,0,IF(S6<=O6,1,0), 1,IF(S6<=P6,1,0),2,IF(S6<=Q6,1,0),3,IF(S6<=R6,1,0)),0)} -> 0
C7: Demarcation | D7: 0.15 | E7: Can your system support automatic demarcation related to core network fault management? Assessment object: core network management function. Core network NE or NFs for assessment: core network NEs (e.g., 5GC NF, EPC NE and IMS NE) | F7: 4 | G7: 3 | H7: 2 | I7: 1 | J7: ='Core Network Fault Management_O'!O6 -> A | K7: =IF(J7="A",F7,IF(J7="B",G7, IF(J7="C",H7, IF(J7="D",I7)))) -> 4 | L7: =K7 -> 4 | O7: D | P7: C | Q7: B | R7: A | S7: =J7 -> A | T7: =IF(S7<=O7,1,0) -> 1 | U7: =IF(S7<=P7,1,0) -> 1 | V7: =IF(S7<=Q7,1,0) -> 1 | W7: =IF(S7<=R7,1,0) -> 1 | Y7: {=_xlfn.SWITCH(X4, 0, IF(O7<N7,1,0),1, IF(P7<O7,1,0), 2, IF(Q7<P7,1,0), 3, IF(R7<Q7,1,0),4,0)} -> 0 | Z7: {=IF(Y7>0,_xlfn.SWITCH(X4,0,IF(S7<=O7,1,0), 1,IF(S7<=P7,1,0),2,IF(S7<=Q7,1,0),3,IF(S7<=R7,1,0)),0)} -> 0
C8: Locating | D8: 0.15 | E8: Does your system support automatic locating related to core network fault management? Assessment object: core network management function and network function. Core network NE or NFs for assessment: core network NEs (e.g., 5GC NF, EPC NE and IMS NE) | F8: 4 | G8: 3 | H8: 2 | I8: 1 | J8: ='Core Network Fault Management_O'!O7 -> A | K8: =IF(J8="A",F8,IF(J8="B",G8, IF(J8="C",H8, IF(J8="D",I8)))) -> 4 | L8: =K8 -> 4 | O8: D | P8: C | Q8: B | R8: A | S8: =J8 -> A | T8: =IF(S8<=O8,1,0) -> 1 | U8: =IF(S8<=P8,1,0) -> 1 | V8: =IF(S8<=Q8,1,0) -> 1 | W8: =IF(S8<=R8,1,0) -> 1 | Y8: {=_xlfn.SWITCH(X4, 0, IF(O8<N8,1,0),1, IF(P8<O8,1,0), 2, IF(Q8<P8,1,0), 3, IF(R8<Q8,1,0),4,0)} -> 0 | Z8: {=IF(Y8>0,_xlfn.SWITCH(X4,0,IF(S8<=O8,1,0), 1,IF(S8<=P8,1,0),2,IF(S8<=Q8,1,0),3,IF(S8<=R8,1,0)),0)} -> 0
B9: Decision | C9: Failure recovery solution generation | D9: 0.1 | E9: Does your system support automatically generate fault recovery solution? Assessment object: core network management function. Core network NE or NFs for assessment: core network NEs (e.g., 5GC NF, EPC NE and IMS NE) | F9: 4 | G9: 3 | H9: 2 | I9: 1 | J9: ='Core Network Fault Management_O'!O8 -> A | K9: =IF(J9="A",F9,IF(J9="B",G9, IF(J9="C",H9, IF(J9="D",I9)))) -> 4 | L9: =K9 -> 4 | O9: D | P9: C | Q9: B | R9: A | S9: =J9 -> A | T9: =IF(S9<=O9,1,0) -> 1 | U9: =IF(S9<=P9,1,0) -> 1 | V9: =IF(S9<=Q9,1,0) -> 1 | W9: =IF(S9<=R9,1,0) -> 1 | Y9: {=_xlfn.SWITCH(X5, 0, IF(O9<N9,1,0),1, IF(P9<O9,1,0), 2, IF(Q9<P9,1,0), 3, IF(R9<Q9,1,0),4,0)} -> 0 | Z9: {=IF(Y9>0,_xlfn.SWITCH(X5,0,IF(S9<=O9,1,0), 1,IF(S9<=P9,1,0),2,IF(S9<=Q9,1,0),3,IF(S9<=R9,1,0)),0)} -> 0
C10: Solution pre-verification | D10: 0.1 | E10: Does your system support recovery solution evaluation and verification to support decision in core network? NOTE: Fault recovery solution can be evaluated before implementation by verification of the solution in a simulation or sandbox environment. Assessment object: core network management function. Core network NE or NFs for assessment: core network NEs (e.g., 5GC NF, EPC NE, IMS NE) | F10: 4 | G10: 3 | H10: 2 | I10: 1 | J10: ='Core Network Fault Management_O'!O9 -> A | K10: =IF(J10="A",F10,IF(J10="B",G10, IF(J10="C",H10, IF(J10="D",I10)))) -> 4 | L10: =K10 -> 4 | O10: D | P10: C | Q10: B | R10: A | S10: =J10 -> A | T10: =IF(S10<=O10,1,0) -> 1 | U10: =IF(S10<=P10,1,0) -> 1 | V10: =IF(S10<=Q10,1,0) -> 1 | W10: =IF(S10<=R10,1,0) -> 1 | Y10: {=_xlfn.SWITCH(X4, 0, IF(O10<N10,1,0),1, IF(P10<O10,1,0), 2, IF(Q10<P10,1,0), 3, IF(R10<Q10,1,0),4,0)} -> 0 | Z10: {=IF(Y10>0,_xlfn.SWITCH(X4,0,IF(S10<=O10,1,0), 1,IF(S10<=P10,1,0),2,IF(S10<=Q10,1,0),3,IF(S10<=R10,1,0)),0)} -> 0
B11: Executions | C11: Solution implementation | D11: 0.1 | E11: Does your system support automatic fault recovery? Assessment object: core network management function, network element. Core network NE or NFs for assessment: core network NEs (e.g., 5GC NF, EPC NE, IMS NE). | F11: 2 | G11: 1 | J11: ='Core Network Fault Management_O'!O10 -> A | K11: =IF(J11="A",F11,IF(J11="B",G11, IF(J11="C",H11, IF(J11="D",I11)))) -> 2 | L11: =IF(AND(K11=2,AVERAGE(K6:K10,K12:K12)>2),AVERAGE(K6:K10,K12:K12),K11) -> 4 | O11: B | P11: A | Q11: A | R11: A | S11: =J11 -> A | T11: =IF(S11<=O11,1,0) -> 1 | U11: =IF(S11<=P11,1,0) -> 1 | V11: =IF(S11<=Q11,1,0) -> 1 | W11: =IF(S11<=R11,1,0) -> 1 | Y11: {=_xlfn.SWITCH(X4, 0, IF(O11<N11,1,0),1, IF(P11<O11,1,0), 2, IF(Q11<P11,1,0), 3, IF(R11<Q11,1,0),4,0)} -> 0 | Z11: {=IF(Y11>0,_xlfn.SWITCH(X4,0,IF(S11<=O11,1,0), 1,IF(S11<=P11,1,0),2,IF(S11<=Q11,1,0),3,IF(S11<=R11,1,0)),0)} -> 0
C12: Service verification | D12: 0.1 | E12: Does your system support automatic service verification of fault recovery related to core network? Assessment object: core network management function Core network NE or NFs for assessment: core network NEs (e.g., 5GC NF, EPC NE, IMS NE). | F12: 4 | G12: 3 | H12: 2 | I12: 1 | J12: ='Core Network Fault Management_O'!O11 -> A | K12: =IF(J12="A",F12,IF(J12="B",G12, IF(J12="C",H12, IF(J12="D",I12)))) -> 4 | L12: =K12 -> 4 | O12: D | P12: C | Q12: B | R12: A | S12: =J12 -> A | T12: =IF(S12<=O12,1,0) -> 1 | U12: =IF(S12<=P12,1,0) -> 1 | V12: =IF(S12<=Q12,1,0) -> 1 | W12: =IF(S12<=R12,1,0) -> 1 | Y12: {=_xlfn.SWITCH(X4, 0, IF(O12<N12,1,0),1, IF(P12<O12,1,0), 2, IF(Q12<P12,1,0), 3, IF(R12<Q12,1,0),4,0)} -> 0 | Z12: {=IF(Y12>0,_xlfn.SWITCH(X4,0,IF(S12<=O12,1,0), 1,IF(S12<=P12,1,0),2,IF(S12<=Q12,1,0),3,IF(S12<=R12,1,0)),0)} -> 0
B14: Note 1: Scores are automatically calculated by formulas, which cannot be changed.
B15: Note 2: Assuming a fault management score of A and a stability score of B, the final score = 50% * score A + 50% * score B.

Sheet Core Network Stability_Orange
A1: Scenario | B1: Category | C1: Capability or Task | D1: Weight (Optional) | E1: Question | F1: Option A | G1: Option B | H1: Option C | I1: Option D | J1: Industry Standard Reference | K1: Option A | L1: Option B | M1: Option C | N1: Option D | O1: Answer | P1: Interpretation on Questions | Q1: Understanding of Options
