Workbook

Sheet Guideline_Orange
B2: I. Introduction
B3: The scope of this questionnaire is to assess CHANGE MANAGEMENT scenario
B4: The assessment is process-based and intended to be vendor-independent and where possible technology independent.
B5: This questionnaire aims to be network layer agnostic, although different evaluations of the same questionnaire are recommended (one per network layer)
B6: Change management comprises the processes of software release management & configuration change management
B7: Configuration changes can be triggered by any process that can change the network equipment configuration (from service provisioning to network evolution). Such changes must include testing before & after the execution. The whole lifecycle of each change must be taken into account: config, delete, modify Some examples: capacity upgrade, network function performance optimization, new parameters or settings configuration, new features activation,…
B8: Software-Release change: takes into account major & minor software updates (including 'patches', for instance, for security)
B9: Such changes must include testing before & after the execution. The whole lifecycle of each change must be taken into account: config, delete, modify
B10: We recommend you have the participation of relevant SMEs to complete the assessment (Engineers as well as automation experts)
B11: Each question is answered by selecting one of four options, A-D, option A being the highest level of autonomy and option D being the lowest
B12: More detailed guidelines per question are provided in the guideline section below
C14: II. Guideline for Answering ANL questionnaire - Version 2
B15: Cognitive Activity (IAADE) | C15: Service Capability | D15: Question | E15: Answering Guideline
B16: Intent | C16: Intent-driven | D16: How are change management activities (any kind of configuration change over the network elements, software upgrades) defined? Intents input can be: new service requirements, resolution of network incident, network performance optimization… | E16: "The role of intent in autonomous networks is to communicate requirements, goals, constraints, and preferences to an autonomous system. This knowledge enables the system to evaluate the state of the controlled infrastructure and the utility of actions. It enables a level of autonomy where the system can adapt its behavior and generate new solutions instead of just following human-defined recipes and policies." IG 1253 Intent in autonomous networks (A) The system reacts to intent or change of intent and generates associated targets and policies autonomously. (B) Same as A but without autonomous reconciliation. No reconciliation or manual confirmation needed in the best scenario (B) The system contains prioritization and SLA information. This data is manually defined. (C) Intent is a fully manual process and targets & policies are defined by a Person, not in a System (D) No intent concept is supported
B17: Awareness | C17: Data collection | D17: How are the inputs for the change management process collected? | E17: (A) The daily operation of the system is fully automatic and requires no human intervention to collect data or perform filtering. The initial set-up activity of the system is considered to be part of Intent. (B) Intermediate state, where the acquisition of part of the systems is autonomous but others require manual intervention. (C) Some level of regular manual intervention to the system is required to collect data (e.g. interrogate the EMS for certain data, select values in combos) (D) Fully manual data collection
B18: Analysis | C18: Analysis | D18: How collected information is analyzed and transform it into knowledge (the input for the decision phase)? | E18: (A) ML or Analytical model correlates multiple data sources automatically to derive knowledge from it. The system is not limited to a set of fixed rules (B) Basic static correlation to analyze data and get some knowledge (fixed rules, user defined) (C) Manual correlation of multiple data sources
C19: Prediction | D19: Which level of prediction capabilities does the change management process support? For instance, for scenarios which can require such capabilities are capacity upgrade (to ensure the Hardware acquisition process is launched in advanced) | E19: (A) or (B) If the scenario involves use of a predictive system, then score A or B according to its capabilities in the specific scenario (C) If the scenario does not use a predictive system, then C is applicable
B20: Decision | C20: Solution evaluation and decision-making | D20: Which level of self-evaluation and self-decision is supported by the change management process? | E20: (A) The system evaluates and decides the solution to be implemented (may be only one possible solution in some cases) (B) Human-guided Automation: a person define a set of solutions to be triggered based on a set of rules based on a predefined list of scenarios. (C) Fully manual evaluation and decision-making by a person
B21: Execution | D21: Remark common to any execution capability | E21: Any automated change (software or configuration) that impact other processes (like crisis management and Disaster Recovery Plan) implies also verification of those processes in an automated way, except when physical aspects are required.
C22: Verification | D22: How are the executions of the change management process tested to ensure no problem has arisen due to the change? | E22: (A) The system evaluates and decides the result of the change based on autonomous service test. System can implement an autonomous roll-back if service test are KO (B) Mix of autonomous and manual tests (C) All tests launched by a person (although automated) (D) All tests are executed manually
C23: Hardware integration | D23: How is new hardware integrated and configured? | E23: (A) Full Plug & play process (B) Some level of automation but not plug & play (C) Fully manual process
C24: Software integration | D24: How is software change management process executed? | E24: (A) System automatically runs software upgrade without any service impact (B) Some automation tools, not for the whole process (C) some level of automation, based on scripts mainly (D) Full manual process
C25: Configuration integration | D25: How are configuration changes executed? | E25: (A) Full autonomous configuration process (B) Automated configuration, human triggered (C) Intermediate: some automated configurations, some still manual, for the same process (D) Full manual process

Sheet Document Title
A7: TM Forum Best Practice
A8: Core Network Change Management Questionnaire
A14: GB1524B
A16: Maturity Level: Beta | B16: Team Approved Date: 25-Mar-2026
A17: Release Status: Pre-production | B17: Approval Status: Team Approved
A18: Version 1.1.0 | B18: IPR Mode: RAND
A26: ©TM Forum 2025. All Rights Reserved.

Sheet Notice
A7: Notice
A8: Copyright © TM Forum 2025. All Rights Reserved.
A10: This document and translations of it may be copied and furnished to others, and derivative works that comment on or otherwise explain it or assist in its implementation may be prepared, copied, published, and distributed, in whole or in part, without restriction of any kind, provided that the above copyright notice and this section are included on all such copies and derivative works. However, this document itself may not be modified in any way, including by removing the copyright notice or references to TM FORUM, except as needed for the purpose of developing any document or deliverable produced by a TM FORUM Collaboration Project Team (in which case the rules applicable to copyrights, as set forth in the TM FORUM IPR Policy, must be followed) or as required to translate it into languages other than English.
A12: The limited permissions granted above are perpetual and will not be revoked by TM FORUM or its successors or assigns.
A14: This document and the information contained herein is provided on an "AS IS" basis and TM FORUM DISCLAIMS ALL WARRANTIES, EXPRESS OR IMPLIED, INCLUDING BUT NOT LIMITED TO ANY WARRANTY THAT THE USE OF THE INFORMATION HEREIN WILL NOT INFRINGE ANY OWNERSHIP RIGHTS OR ANY IMPLIED WARRANTIES OF MERCHANTABILITY OR FITNESS FOR A PARTICULAR PURPOSE.
A16: Direct inquiries to the TM Forum office:
A18: 100 Enterprise Drive
A19: Suite 301 #1649
A20: Rockaway, NJ 07866 USA
A21: Tel No. +1 862 227 1648
A22: TM Forum Web Page: www.tmforum.org
A24: ©TM Forum 2025. All Rights Reserved.

Sheet Guideline
B2: I. Introduction
B3: The purpose of this questionnaire is to assess the autonomy level of Change Management scenarios for Core Networks. The assessment is intended to be vendor-independent
B4: The questionnaire is aligned with the principles described in IG1252 and ETSI GR ENI 035 5.3.3 Network Change. Service Capabilities who are not available, require consensus.
B5: The participation of relevant Subject Matter Experts and automation experts involved in the Change management is required to complete the assessment
B6: Each question is answered by selecting one of the four options: A, B, C or D. Option A being the highest level of autonomy and option D being the lowest
B7: Change management comprises the processes of configuration changes. Configuration changes can be triggered by any process that can change the network equipment configuration (from service provisioning to network evolution). Such changes must include evaluation before & after the execution.
B8: The whole lifecycle of each change management must be taken into account from change submission, until service validation.
B9: Dynamically Programable Rules: implies that the system uses rules that can be adjusted or modified in real-time based on changing conditions or requirements
B10: Sub-scenarios and related weighting are specific to the Communication Service Provider (CSP) and should be selected according to CSP priority and business objectives. Sub-scenarios are domain specific
B11: On the "Scoring" sheet, the assessor should manually link the Option selection on column "J", to the relevant sub-scenario on "Core Network Change Management" sheet.
B12: More detailed guidelines per question are provided in the guideline section below
C14: II. Guideline for Answering ANL Questionnaire
B15: Cognitive Activity (IAADE) | C15: Service Capability | D15: Question | E15: Answering Guideline
B16: Intent | C16: ='[1]Change Management'!C4 -> Intent Translation, & Intent Fulfilment | D16: How does the system handle intent translation, record change requests, and ensure successful intent fulfillment? Note: intent includes but not limited to NEs upgrade、NEs parameter adjustment，one-click disaster recovery for NEs. | E16: (A) Change management Intent is entered by Human. The System translates the Intent to task targets. The System verifies Intent fulfillment based on Human confirmation (B) Intent is expressed through predefined Rules and Policies. Intent fulfilment is manually verified. (C) Change management activities are manually defined through basic templates. Prior to set the Intent, the user should: Understand the end goal of the change, understand the change category and applicable CM policies (lead time for CR, node information/domains, severity/urgency, date/time, impact & risk, fall back, evaluation criteria, approvals and Service Verification duration...)
B17: Awareness | C17: ='[1]Change Management'!C5 -> Change Request Validation & Acceptance | D17: How are the inputs for the change management validated and accepted? | E17: (A) The System automatically validates and accepts the change request, without human intervention (B) The System validates the change request but the change acceptance is manually done. (C) Both change request validation and acceptance are done based on manually defined rules (D) Both validation and acceptance are manually done. Note1: It is assumed that the individual Change Request is recorded in the System and made available to be processed by the Change Management System Note2: Change Request Acceptance (Feasibility) according to Network Policies.
C18: ='[1]Change Management'!C6 -> Change Request Information Collection | D18: How does the System collect necessary information for change request? Note: Necessary information includes but not limited to the NEs /associated NEs to be changed, the change scene and the change time. | E18: (A) The System automatically collects change request information without human intervention. The System can intelligently require and collect the change request information, when key information is incomplete. (B) The System collects change request information but needs human intervention (C) The system collects change request information based on manually defined rules (D) Change request information is collected manually.
B19: Analysis | C19: ='[1]Change Management'!C7 -> Requirements Impact & Risk Analysis | D19: How does the System support network change requirements impact and risk analysis? | E19: (A) The System identifies requirements impacts and evaluate subsequent risk based on AI models without the need for Human intervention. (B) The System identifies requirements impacts and evaluates subsequent risk based on Dynamically Programmable Rules/ML and may require Human confirmation. (C) The System identifies requirements impacts and evaluates subsequent risk based on manually defined rules and templates.. (D) Change impact and risk analysis need to be manually evaluated based on Human expertise or through the execution of manual written procedures.
C20: ='[1]Change Management'!C8 -> Network change Solution Generation | D20: How does the System generate the solution that supports the Change Request? | E20: (A) The System generates the solution based on AI models, without the need for Human intervention. (B) The System generates the solution based on Dynamically Programmable Rules/ML and may require Human confirmation. (C) The System generates the solution based on manually defined rules. (D) Solutions are generated manually.
B21: Decision | C21: ='[1]Change Management'!C9 -> Network Change solution Evaluation & Decision | D21: How does the System support evaluating the solution, taking decision on the optimal solution and initiating approval for the submitted change request? Note: Solution evaluation includes feasibility, alignment with change requests and potential network impact. | E21: (A) The System supports solution evaluation and decision for change request based on AI models, without the need for Human intervention. (B) The System supports decision for change request based on Dynamically Programmable Rules/ML and may require Human confirmation (approval). (C) The System supports solution evaluation and decision for change request based on manually defined rules. (D) The solution evaluation and decision for change request is based on Human approval.
B22: Execution | C22: ='[1]Change Management'!C10 -> Network Normality Verification | D22: How does the System evaluate the normality of the network before the change (including: backup, dial-up and inspection).E.g.: automatic health check Note: Dial-up means simulating a call test to verify network connectivity. | E22: (A) The System verifies the normality of the network based on AI models, without the need for Human intervention. (B) The System verifies the normality of the network based on Dynamically Programmable Rules/ML and may require Human confirmation. (C) The System verifies the normality of the network based on manually defined rules (D) The normality of the network is verified by Human. Note3: Network Change Implementation requires that nothing is broken, before applying the change (claim the outcome of the change implementation)
C23: ='[1]Change Management'!C11 -> Network Change Implementation | D23: How does the System implement the change in the network and roll-back in case of failure? | E23: (A) The System automatically executes changes without Human intervention. If any issue is detected, an automated roll-back will be executed without Human intervention, and the issue report will be provided. If the roll-back fails, the automatic disaster recovery will be activated and excuted without Human intervention. (B) The System executes changes based on manually defined rules. If any issue is detected, roll-back is executed based on Human intervention. If the roll-back fails, the disaster recovery will be activated and executed based on Human intervention (C) Change implementation and roll-back (if necessary) are manually executed.
C24: ='[1]Change Management'!C12 -> Service Verification | D24: How does the System verify and confirm the implementation results, and execute roll-back if the change requirement is not fulfilled? | E24: (A) The System automatically verifies change implementation, and ensures the alarms are cleared and no deterioration of performance, without Human intervention. If the change requirment is not fulfilled, the roll-back will be automatically activated and executed without Human intervention. (B) The System verifies change implementation and checks the corresponding alarms but performance indicators are verified based on Human intervention. If the change requirment is not fulfilled, a roll-back will be activated by Human intervention and automatically executed. (C) The system verifies change implementation but performance indicators and core network element alarms are verified based on manually defines rules. If the change requirment is not fulfilled, a roll-back will be manually executed. (D) Change verification, alarms and performance indicators are manually verified. If the change requirment is not fulfilled, a roll-back will be manually executed. Note4: The Service Verification occurs within the lead time specified for the change request type and policies (After the execution is successfully verified, the standard preventive maintenance checks are in place to manage any deviation outside the maintenance window) Note5: The cognitive loop is closed by Intent Fulfilment verification

Sheet Core Network Change Management
A1: Process Flow | B1: Cognitive Activity (IAADE) | C1: Service Capability | D1: Weight | E1: Question | F1: Option A | G1: Option B | H1: Option C | I1: Option D | K1: Answer | O1: Understanding of selecting the option | P1: Interpretating on question
J2: Standard Reference | K2: Configuration Change | L2: Service Lifecycle Management Changes | M2: Software Upgrade | N2: Other sub-scenarios to be defined by CSP
K3: 0.4 | L3: 0.3 | M3: 0.2 | N3: 0.1
A4: Core Network Change Management | B4: Intent | C4: Intent Translation, Change Request Record & Intent Fulfilment | D4: 0.1 | E4: How does the system handle intent translation, record change requests, and ensure successful intent fulfillment? Note: intent includes but not limited to NEs upgrade、NEs parameter adjustment，one-click disaster recovery for NEs. | F4: Change management Intent is entered by Human. The System translates the Intent to task targets. The System verifies Intent fulfillment based on Human confirmation | G4: Intent is expressed through predefined Rules and Policies. Intent fulfilment is manually verified. | H4: Change management activities are manually defined through basic templates. | J4: ETSI GR ENI 035 5.3.3 Network change- Task: Intent-management | K4: A | L4: A | M4: A | N4: A
B5: Awareness | C5: Change Request Validation & Acceptance | D5: 0.1 | E5: How are the inputs for the change management validated and accepted? | F5: The System automatically validates and accepts change requests without human intervention. | G5: The System validates the change request but the change acceptance is manually done. | H5: Both validation and acceptance are done based on manually defined rules. | I5: Both validation and acceptance are manually done. | K5: A | L5: A | M5: A | N5: A
C6: Change Request Information Collection | D6: 0.1 | E6: How does the System collect necessary information for change request? Note: Necessary information includes but not limited to the NEs /associated NEs to be changed, the change scene and the change time. | F6: The System automatically collects change request information without human intervention. The System can intelligently require and collect the change request information, when key information is incomplete. | G6: The System collects change request information but needs human intervention | H6: The System collects change request information based on manually defined rules. | I6: Change request information is collected manually. | J6: ETSI GR ENI 035 5.3.3 Network change- Task: Resource survey | K6: A | L6: A | M6: A | N6: A
B7: Analysis | C7: Requirements Impact & Risk Analysis | D7: 0.1 | E7: How does the System support network change requirements impact and risk analysis? | F7: The System identifies requirements impacts and evaluate subsequent risk based on AI models without the need for Human intervention. | G7: The System identifies requirements impacts and evaluate subsequent risk based on Dynamically Programmable Rules/ML, and may need Human confirmation | H7: The System identifies requirements impacts and evaluate subsequent risk based on manually defined rules and templates. | I7: Change impact and risk analysis need to be manually evaluated based on Human expertise or through the execution of manual written procedures. | K7: A | L7: A | M7: A | N7: A
C8: Network change Solution Generation | D8: 0.1 | E8: How does the System generate the solution that supports the Change Request? | F8: The System generates the solution based on AI models without the need for Human intervention. | G8: The System generates the solution based on Dynamically Programmable Rules/ML, and may need Human confirmation | H8: The System generates the solution based on manually defined rules. | I8: Solutions are generated manually. | J8: ETSI GR ENI 035 5.3.3 Network change- Task: Change analysis | K8: A | L8: A | M8: A | N8: A
B9: Decision | C9: Network Change solution Evaluation & Decision | D9: 0.2 | E9: How does the System support evaluating the solution, taking decision on the optimal solution and initiating approval for the submitted change request? Note: Solution evaluation includes feasibility, alignment with change requests and potential network impact. | F9: The System supports solution evaluation and decision for change request based on AI models, without the need for Human intervention. | G9: The System supports solution evaluation and decision for change request based on Dynamically Programmable Rules/ML and my need Human confirmation (approval) | H9: The System supports solution evaluation and decision for change request based on manually defined rules. | I9: The solution evaluation and decision for change request is based on Human approval. | J9: ETSI GR ENI 035 5.3.3 Network change- Task: Evaluation and Decision | K9: A | L9: A | M9: A | N9: A
B10: Execution | C10: Network Normality Verification | D10: 0.1 | E10: How does the System evaluate the normality of the network before the change (including: backup, dial-up and inspection).E.g.: automatic health check Note: Dial-up means simulating a call test to verify network connectivity. | F10: The System verifies the normality of the network based on AI models, without the need for Human intervention. | G10: The System verifies the normality of the network based on Dynamically Programmable Rules/ML and may require Human confirmation. | H10: The System verifies the normality of the network based on manually defined rules. | I10: The normality of the network is verified by Human. | K10: A | L10: A | M10: A | N10: A
C11: Network Change Implementation | D11: 0.1 | E11: How does the System implement the change in the network and roll-back in case of failure? | F11: The System automatically executes changes without Human intervention. If any issue is detected, an automated roll-back will be executed without Human intervention, and the issue report will be provided. If the roll-back fails, the automatic disaster recovery will be activated and excuted without Human intervention. Note: Disaster recovery for the core network enables rapid service switching of the core network in the event of faults or disasters through automated technologies, ensuring the continuity of communication services. | G11: The System executes changes based on manually defined rules. If any issue is detected, roll-back is executed based on Human intervention. If the roll-back fails, the disaster recovery will be activated and executed based on Human intervention | H11: Change implementation, roll-back and disaster recovery (if necessary) are manually executed. | J11: ETSI GR ENI 035 5.3.3 Network change- Task: Change implementation and service verification | K11: A | L11: A | M11: A | N11: A
C12: Service Verification | D12: 0.1 | E12: How does the System verify and confirm the implementation results, and execute roll-back if the change requirement is not fulfilled? | F12: The System automatically verifies change implementation, and ensures the alarms are cleared and no deterioration of performance, without Human intervention. If the change requirment is not fulfilled, the roll-back will be automatically activated and executed without Human intervention. Note： For the core network, it is not enough to rely solely on KPI. It is necessary to ensure the normal overall operation of the system, and the performance of software and hardware has not decreased. | G12: The System verifies change implementation and checks the corresponding alarms but performance indicators are verified based on Human intervention. If the change requirment is not fulfilled, a roll-back will be activated by Human intervention and automatically executed. | H12: The system verifies change implementation but performance indicators and core network element alarms are verified based on manually defines rules. If the change requirment is not fulfilled, a roll-back will be manually executed. | I12: Change verification, alarms and performance indicators are manually verified. If the change requirment is not fulfilled, a roll-back will be manually executed. | J12: ETSI GR ENI 035 5.3.3 Network change- Task: Change implementation and service verification | K12: A | L12: A | M12: A | N12: A
D13: =SUM(D4:D12) -> 1 | K13: Note: Configuration change denotes modifications to parameters, policies, routing, or logical relationships of NEs | L13: Note: Service lifecycle management changes include new service provisioning, function deployment changes and decommissioning and coordinated with surrounding changes | M13: Note：Software change involves changes for version upgrades, and patch installations.

Sheet Scoring
A1: Process Flow | B1: Cognitive Activity (IAADE) | C1: Service Capability | D1: Weight | E1: Question | F1: Scoring Method - Average | J1: Scoring Method of Subscenarios
F2: Criteria | J2: Answer | N2: Configuration Change | Q2: Service Lifecycle Management Changes | T2: Software Upgrade | W2: Other sub-scenarios defined by CSP | Z2: Final Score
F3: Option A | G3: Option B | H3: Option C | I3: Option D | J3: Configuration Change | K3: Service Change | L3: Software Upgrade | M3: Other sub-scenarios to be defined by CSP | N3: 0.4 | Q3: 0.3 | T3: 0.2 | W3: 0.1
N4: Original score | O4: Compensated score | P4: Overall Score | Q4: Original score | R4: Compensated score | S4: Overall Score | T4: Original score | U4: Compensated score | V4: Overall Score | W4: Original score | X4: Compensated score | Y4: Overall Score
A5: Core Network Change Management | B5: Intent | C5: Intent Translation, Change Request Record & Intent Fulfilment | D5: 0.1 | E5: How does the system handle intent translation, record change requests, and ensure successful intent fulfillment? Note: intent includes but not limited to NEs upgrade、NEs parameter adjustment，one-click disaster recovery for NEs. | F5: 4 | G5: 3 | H5: 2 | I5: 0 | J5: ='Core Network Change Management'!K4 -> A | K5: ='Core Network Change Management'!L4 -> A | L5: ='Core Network Change Management'!M4 -> A | M5: ='Core Network Change Management'!N4 -> A | N5: =IF(J5="A",F5,IF(J5="B",G5,IF(J5="C",H5,IF(J5="D",I5)))) -> 4 | O5: =N5 -> 4 | P5: =AVERAGE(O5:O13) -> 4 | Q5: =IF(K5="A",F5,IF(K5="B",G5,IF(K5="C",H5,IF(K5="D",I5)))) -> 4 | R5: =Q5 -> 4 | S5: =AVERAGE(R5:R13) -> 4 | T5: =IF(L5="A",F5,IF(L5="B",G5,IF(L5="C",H5,IF(L5="D",I5)))) -> 4 | U5: =T5 -> 4 | V5: =AVERAGE(U5:U13) -> 4 | W5: =IF(M5="A",F5,IF(M5="B",G5,IF(M5="C",H5,IF(M5="D",I5)))) -> 4 | X5: =W5 -> 4 | Y5: =AVERAGE(X5:X13) -> 4 | Z5: =(P5*N3+S5*Q3+V5*T3+Y5*W3)/(N3+Q3+T3+W3) -> 4
B6: Awareness | C6: Change Request Validation & Acceptance | D6: 0.1 | E6: How are the inputs for the change management validated and accepted? | F6: 3 | G6: 2 | H6: 1 | I6: 0 | J6: ='Core Network Change Management'!K5 -> A | K6: ='Core Network Change Management'!L5 -> A | L6: ='Core Network Change Management'!M5 -> A | M6: ='Core Network Change Management'!N5 -> A | N6: =IF(J6="A",F6,IF(J6="B",G6,IF(J6="C",H6,IF(J6="D",I6)))) -> 3 | O6: =IF(AND(N6=3,AVERAGE(N5,N8,N9,N10,N11,N13)>3),AVERAGE(N5,N8,N9,N10,N11,N13),N6) -> 4 | Q6: =IF(K6="A",F6,IF(K6="B",G6,IF(K6="C",H6,IF(K6="D",I6)))) -> 3 | R6: =IF(AND(Q6=3,AVERAGE(Q5,Q8,Q9,Q10,Q11,Q13)>3),AVERAGE(Q5,Q8,Q9,Q10,Q11,Q13),Q6) -> 4 | T6: =IF(L6="A",F6,IF(L6="B",G6,IF(L6="C",H6,IF(L6="D",I6)))) -> 3 | U6: =IF(AND(T6=3,AVERAGE(T5,T8,T9,T10,T11,T13)>3),AVERAGE(T5,T8,T9,T10,T11,T13),T6) -> 4 | W6: =IF(M6="A",F6,IF(M6="B",G6,IF(M6="C",H6,IF(M6="D",I6)))) -> 3 | X6: =IF(AND(W6=3,AVERAGE(W5,W8,W9,W10,W11,W13)>3),AVERAGE(W5,W8,W9,W10,W11,W13),W6) -> 4
C7: Change Request Information Collection | D7: 0.1 | E7: How does the System collect necessary information for change request? Note: Necessary information includes but not limited to the NEs /associated NEs to be changed, the change scene and the change time. | F7: 3 | G7: 2 | H7: 1 | I7: 0 | J7: ='Core Network Change Management'!K6 -> A | K7: ='Core Network Change Management'!L6 -> A | L7: ='Core Network Change Management'!M6 -> A | M7: ='Core Network Change Management'!N6 -> A | N7: =IF(J7="A",F7,IF(J7="B",G7,IF(J7="C",H7,IF(J7="D",I7)))) -> 3 | O7: =IF(AND(N7=3,AVERAGE(N5,N8,N9,N10,N11,N13)>3),AVERAGE(N5,N8,N9,N10,N11,N13),N7) -> 4 | Q7: =IF(K7="A",F7,IF(K7="B",G7,IF(K7="C",H7,IF(K7="D",I7)))) -> 3 | R7: =IF(AND(Q7=3,AVERAGE(Q5,Q8,Q9,Q10,Q11,Q13)>3),AVERAGE(Q5,Q8,Q9,Q10,Q11,Q13),Q7) -> 4 | T7: =IF(L7="A",F7,IF(L7="B",G7,IF(L7="C",H7,IF(L7="D",I7)))) -> 3 | U7: =IF(AND(T7=3,AVERAGE(T5,T8,T9,T10,T11,T13)>3),AVERAGE(T5,T8,T9,T10,T11,T13),T7) -> 4 | W7: =IF(M7="A",F7,IF(M7="B",G7,IF(M7="C",H7,IF(M7="D",I7)))) -> 3 | X7: =IF(AND(W7=3,AVERAGE(W5,W8,W9,W10,W11,W13)>3),AVERAGE(W5,W8,W9,W10,W11,W13),W7) -> 4
B8: Analysis | C8: Requirements Impact & Risk Analysis | D8: 0.1 | E8: How does the System support network change requirements impact and risk analysis? | F8: 4 | G8: 3 | H8: 2 | I8: 1 | J8: ='Core Network Change Management'!K7 -> A | K8: ='Core Network Change Management'!L7 -> A | L8: ='Core Network Change Management'!M7 -> A | M8: ='Core Network Change Management'!N7 -> A | N8: =IF(J8="A",F8,IF(J8="B",G8,IF(J8="C",H8,IF(J8="D",I8)))) -> 4 | O8: =N8 -> 4 | Q8: =IF(K8="A",F8,IF(K8="B",G8,IF(K8="C",H8,IF(K8="D",I8)))) -> 4 | R8: =Q8 -> 4 | T8: =IF(L8="A",F8,IF(L8="B",G8,IF(L8="C",H8,IF(L8="D",I8)))) -> 4 | U8: =T8 -> 4 | W8: =IF(M8="A",F8,IF(M8="B",G8,IF(M8="C",H8,IF(M8="D",I8)))) -> 4 | X8: =W8 -> 4
C9: Network change Solution Generation | D9: 0.1 | E9: How does the System generate the solution that supports the Change Request? | F9: 4 | G9: 3 | H9: 2 | I9: 1 | J9: ='Core Network Change Management'!K8 -> A | K9: ='Core Network Change Management'!L8 -> A | L9: ='Core Network Change Management'!M8 -> A | M9: ='Core Network Change Management'!N8 -> A | N9: =IF(J9="A",F9,IF(J9="B",G9,IF(J9="C",H9,IF(J9="D",I9)))) -> 4 | O9: =N9 -> 4 | Q9: =IF(K9="A",F9,IF(K9="B",G9,IF(K9="C",H9,IF(K9="D",I9)))) -> 4 | R9: =Q9 -> 4 | T9: =IF(L9="A",F9,IF(L9="B",G9,IF(L9="C",H9,IF(L9="D",I9)))) -> 4 | U9: =T9 -> 4 | W9: =IF(M9="A",F9,IF(M9="B",G9,IF(M9="C",H9,IF(M9="D",I9)))) -> 4 | X9: =W9 -> 4
B10: Decision | C10: Network Change solution Evaluation & Decision | D10: 0.2 | E10: How does the System support evaluating the solution, taking decision on the optimal solution and initiating approval for the submitted change request? | F10: 4 | G10: 3 | H10: 2 | I10: 1 | J10: ='Core Network Change Management'!K9 -> A | K10: ='Core Network Change Management'!L9 -> A | L10: ='Core Network Change Management'!M9 -> A | M10: ='Core Network Change Management'!N9 -> A | N10: =IF(J10="A",F10,IF(J10="B",G10,IF(J10="C",H10,IF(J10="D",I10)))) -> 4 | O10: =N10 -> 4 | Q10: =IF(K10="A",F10,IF(K10="B",G10,IF(K10="C",H10,IF(K10="D",I10)))) -> 4 | R10: =Q10 -> 4 | T10: =IF(L10="A",F10,IF(L10="B",G10,IF(L10="C",H10,IF(L10="D",I10)))) -> 4 | U10: =T10 -> 4 | W10: =IF(M10="A",F10,IF(M10="B",G10,IF(M10="C",H10,IF(M10="D",I10)))) -> 4 | X10: =W10 -> 4
B11: Execution | C11: Network Normality Evaluation | D11: 0.1 | E11: How does the System evaluate the normality of the network before the change (including: automatic backup, automatic dial-up and automatic inspection) | F11: 4 | G11: 3 | H11: 2 | I11: 1 | J11: ='Core Network Change Management'!K10 -> A | K11: ='Core Network Change Management'!L10 -> A | L11: ='Core Network Change Management'!M10 -> A | M11: ='Core Network Change Management'!N10 -> A | N11: =IF(J11="A",F11,IF(J11="B",G11,IF(J11="C",H11,IF(J11="D",I11)))) -> 4 | O11: =N11 -> 4 | Q11: =IF(K11="A",F11,IF(K11="B",G11,IF(K11="C",H11,IF(K11="D",I11)))) -> 4 | R11: =Q11 -> 4 | T11: =IF(L11="A",F11,IF(L11="B",G11,IF(L11="C",H11,IF(L11="D",I11)))) -> 4 | U11: =T11 -> 4 | W11: =IF(M11="A",F11,IF(M11="B",G11,IF(M11="C",H11,IF(M11="D",I11)))) -> 4 | X11: =W11 -> 4
C12: Network Change Implementation | D12: 0.1 | E12: How does the System implement the change in the network and roll-back in case of failure? | F12: 2 | G12: 1 | H12: 0 | I12: 0 | J12: ='Core Network Change Management'!K11 -> A | K12: ='Core Network Change Management'!L11 -> A | L12: ='Core Network Change Management'!M11 -> A | M12: ='Core Network Change Management'!N11 -> A | N12: =IF(J12="A",F12,IF(J12="B",G12,IF(J12="C",H12,IF(J12="D",I12)))) -> 2 | O12: =IF(AND(N12=2,AVERAGE(N5,N8,N9,N10,N11,N13)>2),AVERAGE(N5,N8,N9,N10,N11,N13),N12) -> 4 | Q12: =IF(K12="A",F12,IF(K12="B",G12,IF(K12="C",H12,IF(K12="D",I12)))) -> 2 | R12: =IF(AND(Q12=2,AVERAGE(Q5,Q8,Q9,Q10,Q11,Q13)>2),AVERAGE(Q5,Q8,Q9,Q10,Q11,Q13),Q12) -> 4 | T12: =IF(L12="A",F12,IF(L12="B",G12,IF(L12="C",H12,IF(L12="D",I12)))) -> 2 | U12: =IF(AND(T7=3,AVERAGE(T5,T8,T9,T10,T11,T13)>3),AVERAGE(T5,T8,T9,T10,T11,T13),T7) -> 4 | W12: =IF(M12="A",F12,IF(M12="B",G12,IF(M12="C",H12,IF(M12="D",I12)))) -> 2 | X12: =IF(AND(W12=2,AVERAGE(W5,W8,W9,W10,W11,W13)>2),AVERAGE(W5,W8,W9,W10,W11,W13),W12) -> 4
C13: Service Verification | D13: 0.1 | E13: How does the System verify and confirm the implementation results? | F13: 4 | G13: 3 | H13: 2 | I13: 1 | J13: ='Core Network Change Management'!K12 -> A | K13: ='Core Network Change Management'!L12 -> A | L13: ='Core Network Change Management'!M12 -> A | M13: ='Core Network Change Management'!N12 -> A | N13: =IF(J13="A",F13,IF(J13="B",G13,IF(J13="C",H13,IF(J13="D",I13)))) -> 4 | O13: =N13 -> 4 | Q13: =IF(K13="A",F13,IF(K13="B",G13,IF(K13="C",H13,IF(K13="D",I13)))) -> 4 | R13: =Q13 -> 4 | T13: =IF(L13="A",F13,IF(L13="B",G13,IF(L13="C",H13,IF(L13="D",I13)))) -> 4 | U13: =T13 -> 4 | W13: =IF(M13="A",F13,IF(M13="B",G13,IF(M13="C",H13,IF(M13="D",I13)))) -> 4 | X13: =W13 -> 4
D14: =SUM(D5:D13) -> 1

Sheet Administrative Appendix
A6: Administrative Appendix
A7: Document History
A9: Version History
A10: Version Number | B10: Date Modified | C10: Modified by: | D10: Description of Change
A11: 1.0.0 | B11: 45919 | C11: Alan Pope | D11: Final edits prior to publication
A14: Release History
A15: Release Status | B15: Date Modified | C15: Modified by: | D15: Description of Change
A16: Pre-production | B16: 45919 | C16: Alan Pope | D16: Initial Release
A19: Acknowledgements
A21: This document was prepared by the members of the Autonomous Networks Project team.
A22: Team Member (@mention) | B22: Company | C22: Role*
A23: Kevin McDonnell | B23: Huawei | C23: Project Chair
A24: Pedro Garcia Parra | B24: Telefónica | C24: Project Co-Chair
A25: Fernando Camacho | B25: Huawei | C25: Project Co-Chair
A26: Meng You | B26: China Mobile | C26: Author
A27: Yu He | B27: China Mobile | C27: Author
A28: Jiayi Cai | B28: China Mobile | C28: Author
A29: Xin Gao | B29: China Mobile | C29: Author
A30: Ruowei Yin | B30: China Mobile Group Design Institute Co., Ltd. | C30: Author
A31: Nan Cheng | B31: China Mobile Group Design Institute Co., Ltd. | C31: Author
A32: Xuefeng Han | B32: China Mobile Group Design Institute Co., Ltd. | C32: Author
A33: Ruopei Guo | B33: China Mobile Group Design Institute Co., Ltd. | C33: Author
... A62: Alan Pope | B62: TM Forum | C62: Reviewer, Editor
A64: *Selected from: Project Chair, Project Co-Chair, Author, Editor, Key Contributor, Additional Input, Reviewer

Sheet Change Management_Orange
A1: High-Value Scenario | B1: Cognitive Activity (IAADE) | C1: Service Capability | D1: Weight | E1: Question | F1: Option A | G1: Option B | H1: Option C | I1: Option D | J1: Option A | K1: Option B | L1: Option C | M1: Option D | N1: Answer | O1: Interpretating on question | P1: Understanding of selecting the option
A2: Change management | B2: Intent | C2: Intent-driven | D2: 0.1 | E2: How are change management activities (any kind of configuration change over the network elements, software upgrades) defined? Intents input can be: new service requirements, resolution of network incident, network performance optimization… | F2: Change management is requested through intent-based (declarative) API, which are able to translate high-level intents into task targets and policies. As an intent, there's a continuous reconciliation to ensure that the intent is always respected. | G2: Change management is requested through intent-based (declarative) APIs, which are able to translate high-level intents into task targets and policies. There's no continuous control to ensure the intent is respected. | H2: Change management activities are defined in imperative way through workflows and/or basic "templates". | I2: Neither intent nor imperative APIs are used. Every change management task requires a specific design (‘Low Level Design) | J2: 4 | K2: 3 | L2: 1 | M2: 0 | N2: B
B3: Awareness | C3: Data collection | D3: 0.05 | E3: How are the inputs for the change management process collected? | F3: All the inputs are automatically collected (from OSS tools, inventories, network reconciliation process, supplier artifacts repositories…) | G3: Some inputs are collected automatically but others require human intervention. | H3: The inputs require manual selection from a portal or similar tool (simplifying data acquisition) | I3: Fully manual acquisition process of the inputs | J3: 3 | K3: 2 | L3: 1 | M3: 0 | N3: C
B4: Analysis | C4: Analysis | D4: 0.1 | E4: How collected information is analyzed and transform it into knowledge (the input for the decision phase)? | F4: Information is translated into knowledge thanks to dynamic (intelligent) rules | G4: The system can automatically make an analysis of the situation based on statically defined rules | H4: Fully human-driven analysis process | J4: 4 | K4: 3 | L4: 0 | N4: C
C5: Prediction | D5: 0.15 | E5: Which level of prediction capabilities does the change management process support? For instance, for scenarios which can require such capabilities are capacity upgrade (to ensure the Hardware acquisition process is launched in advanced) | F5: The system is able to inform of future events (based on dynamic / intelligent rules) to ensure that actions (mainly non-automated ones) can be executed before they are needed. | G5: The system can identify potential future change management events based on manually defined (static) rules | H5: Prediction of future change management events must be human-driven | J5: 4 | K5: 3 | L5: 0 | N5: A
B6: Decision | C6: Solution evaluation and decision-making | D6: 0.15 | E6: Which level of self-evaluation and self-decision is supported by the change management process? | F6: The system automatically evaluates and determines the optimal action to fulfill the intent, based on dynamic rules. | G6: The system automatically evaluates and decides the action to execute based on static policy rules. | H6: The optimal solution needs to be manually evaluated and decided. | J6: 4 | K6: 3 | L6: 1 | N6: A
B7: Execution | C7: Verification | D7: 0.1 | E7: How are the executions of the change management process tested to ensure no problem has arisen due to the change? | F7: Changes are tested automatically during the change execution. If any issue is detected (with the service or with any other related service that could be impacted by the change), an automated roll-back is executed | G7: Some automated tests are available and are automatically triggered during the execution. If an error is detected, automated roll-back is executed. Other tests remain to be human-triggered | H7: Only some automated tests are available but need to be triggered by human operator to check the execution result. No automated roll-back | I7: Manual tests are executed to check the result of the change | J7: 3 | K7: 2 | L7: 1 | M7: 0 | N7: A
C8: Hardware integration | D8: 0.05 | E8: How is new hardware integrated and configured? | F8: Hardware installation is done through a zero-touch process (fully plug and play) | G8: Some of the process is automated but not zero-touch level is reached. | H8: Full manual process. | J8: 2 | K8: 1 | L8: 0 | N8: A
C9: Software integration | D9: 0.15 | E9: How is software change management process executed? | F9: Software upgrade/update can be done continuously with no human intervention and none or limited service impact. | G9: Software upgrade process is automated but in different steps that require human intervention to execute all the different steps. Some automation developments are intent-based; most of the automation are just simple scripts | H9: Some automation tools, and some software change/Release done remotely without any physical presence on the site | I9: Full manual process, with possible vendor tool assistance. | J9: 3 | K9: 2 | L9: 1 | M9: 0 | N9: A
C10: Configuration integration | D10: 0.15 | E10: How are configuration changes executed? | F10: The system can autonomously execute the configurations (and service/resource inventory) with no human intervention during the execution (not even to report the execution result). Intent-based execution. | G10: Humans use the system to trigger an automated execution of the configuration, through intent-based orchestrators. | H10: Humans are involved in the configuration change process. Part of the process is automated (although mainly with scripts) but other parts are still manual. | I10: Full manual process. | J10: 3 | K10: 2 | L10: 1 | M10: 0 | N10: A
D11: =SUM(D2:D10) -> 1
A12: Note: 1) The questionnaire is intended for pilot use and will serve as input for future standardization efforts. 2) It is subject to change as the pilot progresses.

Sheet Scoring_Orange
A1: High-Value Scenario | B1: Cognitive Activity (IAADE) | C1: Service Capability | D1: Weight | E1: Question | F1: Method 1: Average | N1: Method 2: Climbing
F2: Criteria | J2: Answer | K2: Calculate | N2: Criteria | S2: Answer | T2: Calculate
F3: Option A | G3: Option B | H3: Option C | I3: Option D | K3: Original score | L3: Compensated score | M3: Overall Score | N3: Level 0 | O3: Level 1 | P3: Level 2 | Q3: Level 3 | R3: Level 4 | T3: Meet Level1 Criteria? | U3: Meet Level2 Criteria? | V3: Meet Level3 Criteria? | W3: Meet Level4 Criteria? | X3: Level Base | Y3: Next Level Require | Z3: Meet Next Level Require | AA3: Level Extra | AB3: Overall Score
A4: Change management | B4: Intent | C4: Intent-driven | D4: 0.1 | E4: How are change management activities (any kind of configuration change over the network elements, software upgrades) defined? Intents input can be: new service requirements, resolution of network incident, network performance optimization… | F4: ='Change Management_Orange'!J2 -> 4 | G4: ='Change Management_Orange'!K2 -> 3 | H4: ='Change Management_Orange'!L2 -> 1 | I4: ='Change Management_Orange'!M2 -> 0 | J4: ='Change Management_Orange'!N2 -> B | K4: =IF(J4="A",F4,IF(J4="B",G4,IF(J4="C",H4,IF(J4="D",I4)))) -> 3 | L4: =K4 -> 3 | M4: =SUMPRODUCT(L4:L12,D4:D12) -> 2.85 | N4: D | O4: D | P4: C | Q4: B | R4: A | S4: =J4 -> B | T4: =IF(S4=0,0,IF(S4<=O4,1,0)) -> 1 | U4: =IF(S4=0,0,IF(S4<=P4,1,0)) -> 1 | V4: =IF(S4=0,0,IF(S4<=Q4,1,0)) -> 1 | W4: =IF(S4=0,0,IF(S4<=R4,1,0)) -> 0 | X4: =IF(AVERAGE(W4:W12)=1,4,IF(AVERAGE(V4:V12)=1,3,IF(AVERAGE(U4:U12)=1,2,IF(AVERAGE(T4:T12)=1,1,0)))) -> 2 | Y4: {=_xlfn.SWITCH(X4,0,IF(O4<N4,1,0),1,IF(P4<O4,1,0),2,IF(Q4<P4,1,0),3,IF(R4<Q4,1,0),4,0)} -> 1 | Z4: {=IF(Y4>0,_xlfn.SWITCH(X4,0,IF(S4<=O4,1,0),1,IF(S4<=P4,1,0),2,IF(S4<=Q4,1,0),3,IF(S4<=R4,1,0)),0)} -> 1 | AA4: =IF(IF(X4=4,0,SUMPRODUCT(Z4:Z12,D4:D12))/IF(SUMPRODUCT(Y4:Y12,D4:D12)=0,1,SUMPRODUCT(Y4:Y12,D4:D12))=1,0,IF(X4=4,0,SUMPRODUCT(Z4:Z12,D4:D12))/IF(SUMPRODUCT(Y4:Y12,D4:D12)=0,1,SUMPRODUCT(Y4:Y12,D4:D12))) -> 0 | AB4: =AA4+X4 -> 2
B5: Awareness | C5: Data collection | D5: 0.05 | E5: How are the inputs for the change management process collected? | F5: ='Change Management_Orange'!J3 -> 3 | G5: ='Change Management_Orange'!K3 -> 2 | H5: ='Change Management_Orange'!L3 -> 1 | I5: ='Change Management_Orange'!M3 -> 0 | J5: ='Change Management_Orange'!N3 -> C | K5: =IF(J5="A",F5,IF(J5="B",G5,IF(J5="C",H5,IF(J5="D",I5)))) -> 1 | L5: =IF(AND(K5=3,AVERAGE($K$4,$K$6,$K$7,$K$8)>3),AVERAGE($K$4,$K$6,$K$7,$K$8),K5) -> 1 | N5: D | O5: D | P5: C | Q5: B | R5: A | S5: =J5 -> C | T5: =IF(S5=0,0,IF(S5<=O5,1,0)) -> 1 | U5: =IF(S5=0,0,IF(S5<=P5,1,0)) -> 1 | V5: =IF(S5=0,0,IF(S5<=Q5,1,0)) -> 0 | W5: =IF(S5=0,0,IF(S5<=R5,1,0)) -> 0 | Y5: {=_xlfn.SWITCH(X5,0,IF(O5<N5,1,0),1,IF(P5<O5,1,0),2,IF(Q5<P5,1,0),3,IF(R5<Q5,1,0),4,0)} -> 0 | Z5: {=IF(Y5>0,_xlfn.SWITCH(X5,0,IF(S5<=O5,1,0),1,IF(S5<=P5,1,0),2,IF(S5<=Q5,1,0),3,IF(S5<=R5,1,0)),0)} -> 0
B6: Analysis | C6: Analysis | D6: 0.1 | E6: How collected information is analyzed and transform it into knowledge (the input for the decision phase)? | F6: ='Change Management_Orange'!J4 -> 4 | G6: ='Change Management_Orange'!K4 -> 3 | H6: ='Change Management_Orange'!L4 -> 0 | I6: ='Change Management_Orange'!M4 -> 0 | J6: ='Change Management_Orange'!N4 -> C | K6: =IF(J6="A",F6,IF(J6="B",G6,IF(J6="C",H6,IF(J6="D",I6)))) -> 0 | L6: =K6 -> 0 | N6: C | O6: C | P6: C | Q6: B | R6: A | S6: =J6 -> C | T6: =IF(S6=0,0,IF(S6<=O6,1,0)) -> 1 | U6: =IF(S6=0,0,IF(S6<=P6,1,0)) -> 1 | V6: =IF(S6=0,0,IF(S6<=Q6,1,0)) -> 0 | W6: =IF(S6=0,0,IF(S6<=R6,1,0)) -> 0 | Y6: {=_xlfn.SWITCH(X6,0,IF(O6<N6,1,0),1,IF(P6<O6,1,0),2,IF(Q6<P6,1,0),3,IF(R6<Q6,1,0),4,0)} -> 0 | Z6: {=IF(Y6>0,_xlfn.SWITCH(X6,0,IF(S6<=O6,1,0),1,IF(S6<=P6,1,0),2,IF(S6<=Q6,1,0),3,IF(S6<=R6,1,0)),0)} -> 0
C7: Prediction | D7: 0.15 | E7: Which level of prediction capabilities does the change management process support? For instance, for scenarios which can require such capabilities are capacity upgrade (to ensure the Hardware acquisition process is launched in advanced) | F7: ='Change Management_Orange'!J5 -> 4 | G7: ='Change Management_Orange'!K5 -> 3 | H7: ='Change Management_Orange'!L5 -> 0 | I7: ='Change Management_Orange'!M5 -> 0 | J7: ='Change Management_Orange'!N5 -> A | K7: =IF(J7="A",F7,IF(J7="B",G7,IF(J7="C",H7,IF(J7="D",I7)))) -> 4 | L7: =K7 -> 4 | N7: C | O7: C | P7: B | Q7: A | R7: A | S7: =J7 -> A | T7: =IF(S7=0,0,IF(S7<=O7,1,0)) -> 1 | U7: =IF(S7=0,0,IF(S7<=P7,1,0)) -> 1 | V7: =IF(S7=0,0,IF(S7<=Q7,1,0)) -> 1 | W7: =IF(S7=0,0,IF(S7<=R7,1,0)) -> 1 | Y7: {=_xlfn.SWITCH(X7,0,IF(O7<N7,1,0),1,IF(P7<O7,1,0),2,IF(Q7<P7,1,0),3,IF(R7<Q7,1,0),4,0)} -> 0 | Z7: {=IF(Y7>0,_xlfn.SWITCH(X7,0,IF(S7<=O7,1,0),1,IF(S7<=P7,1,0),2,IF(S7<=Q7,1,0),3,IF(S7<=R7,1,0)),0)} -> 0
B8: Decision | C8: Solution evaluation and decision-making | D8: 0.15 | E8: Which level of self-evaluation and self-decision is supported by the change management process? | F8: ='Change Management_Orange'!J6 -> 4 | G8: ='Change Management_Orange'!K6 -> 3 | H8: ='Change Management_Orange'!L6 -> 1 | I8: ='Change Management_Orange'!M6 -> 0 | J8: ='Change Management_Orange'!N6 -> A | K8: =IF(J8="A",F8,IF(J8="B",G8,IF(J8="C",H8,IF(J8="D",I8)))) -> 4 | L8: =K8 -> 4 | N8: D | O8: D | P8: C | Q8: B | R8: A | S8: =J8 -> A | T8: =IF(S8=0,0,IF(S8<=O8,1,0)) -> 1 | U8: =IF(S8=0,0,IF(S8<=P8,1,0)) -> 1 | V8: =IF(S8=0,0,IF(S8<=Q8,1,0)) -> 1 | W8: =IF(S8=0,0,IF(S8<=R8,1,0)) -> 1 | Y8: {=_xlfn.SWITCH(X8,0,IF(O8<N8,1,0),1,IF(P8<O8,1,0),2,IF(Q8<P8,1,0),3,IF(R8<Q8,1,0),4,0)} -> 0 | Z8: {=IF(Y8>0,_xlfn.SWITCH(X8,0,IF(S8<=O8,1,0),1,IF(S8<=P8,1,0),2,IF(S8<=Q8,1,0),3,IF(S8<=R8,1,0)),0)} -> 0
B9: Execution | C9: Testing | D9: 0.1 | E9: How are the executions of the change management process tested to ensure no problem has arisen due to the change? | F9: ='Change Management_Orange'!J7 -> 3 | G9: ='Change Management_Orange'!K7 -> 2 | H9: ='Change Management_Orange'!L7 -> 1 | I9: ='Change Management_Orange'!M7 -> 0 | J9: ='Change Management_Orange'!N7 -> A | K9: =IF(J9="A",F9,IF(J9="B",G9,IF(J9="C",H9,IF(J9="D",I9)))) -> 3 | L9: =IF(AND(K9=3,AVERAGE($K$4,$K$6,$K$7,$K$8)>3),AVERAGE($K$4,$K$6,$K$7,$K$8),K9) -> 3 | N9: C | O9: C | P9: C | Q9: B | R9: A | S9: =J9 -> A | T9: =IF(S9=0,0,IF(S9<=O9,1,0)) -> 1 | U9: =IF(S9=0,0,IF(S9<=P9,1,0)) -> 1 | V9: =IF(S9=0,0,IF(S9<=Q9,1,0)) -> 1 | W9: =IF(S9=0,0,IF(S9<=R9,1,0)) -> 1 | Y9: {=_xlfn.SWITCH(X9,0,IF(O9<N9,1,0),1,IF(P9<O9,1,0),2,IF(Q9<P9,1,0),3,IF(R9<Q9,1,0),4,0)} -> 0 | Z9: {=IF(Y9>0,_xlfn.SWITCH(X9,0,IF(S9<=O9,1,0),1,IF(S9<=P9,1,0),2,IF(S9<=Q9,1,0),3,IF(S9<=R9,1,0)),0)} -> 0
C10: Hardware | D10: 0.05 | E10: How is new hardware integrated and configured? | F10: ='Change Management_Orange'!J8 -> 2 | G10: ='Change Management_Orange'!K8 -> 1 | H10: ='Change Management_Orange'!L8 -> 0 | I10: ='Change Management_Orange'!M8 -> 0 | J10: ='Change Management_Orange'!N8 -> A | K10: =IF(J10="A",F10,IF(J10="B",G10,IF(J10="C",H10,IF(J10="D",I10)))) -> 2 | L10: =IF(AND(K10=2,AVERAGE($K$4,$K$6,$K$7,$K$8)>3),AVERAGE($K$4,$K$6,$K$7,$K$8),K10) -> 2 | N10: C | O10: C | P10: C | Q10: B | R10: A | S10: =J10 -> A | T10: =IF(S10=0,0,IF(S10<=O10,1,0)) -> 1 | U10: =IF(S10=0,0,IF(S10<=P10,1,0)) -> 1 | V10: =IF(S10=0,0,IF(S10<=Q10,1,0)) -> 1 | W10: =IF(S10=0,0,IF(S10<=R10,1,0)) -> 1 | Y10: {=_xlfn.SWITCH(X10,0,IF(O10<N10,1,0),1,IF(P10<O10,1,0),2,IF(Q10<P10,1,0),3,IF(R10<Q10,1,0),4,0)} -> 0 | Z10: {=IF(Y10>0,_xlfn.SWITCH(X10,0,IF(S10<=O10,1,0),1,IF(S10<=P10,1,0),2,IF(S10<=Q10,1,0),3,IF(S10<=R10,1,0)),0)} -> 0
C11: Software | D11: 0.15 | E11: How is software change management process executed? | F11: ='Change Management_Orange'!J9 -> 3 | G11: ='Change Management_Orange'!K9 -> 2 | H11: ='Change Management_Orange'!L9 -> 1 | I11: ='Change Management_Orange'!M9 -> 0 | J11: ='Change Management_Orange'!N9 -> A | K11: =IF(J11="A",F11,IF(J11="B",G11,IF(J11="C",H11,IF(J11="D",I11)))) -> 3 | L11: =IF(AND(K11=3,AVERAGE($K$4,$K$6,$K$7,$K$8)>3),AVERAGE($K$4,$K$6,$K$7,$K$8),K11) -> 3 | N11: D | O11: D | P11: C | Q11: B | R11: A | S11: =J11 -> A | T11: =IF(S11=0,0,IF(S11<=O11,1,0)) -> 1 | U11: =IF(S11=0,0,IF(S11<=P11,1,0)) -> 1 | V11: =IF(S11=0,0,IF(S11<=Q11,1,0)) -> 1 | W11: =IF(S11=0,0,IF(S11<=R11,1,0)) -> 1 | Y11: {=_xlfn.SWITCH(X11,0,IF(O11<N11,1,0),1,IF(P11<O11,1,0),2,IF(Q11<P11,1,0),3,IF(R11<Q11,1,0),4,0)} -> 0 | Z11: {=IF(Y11>0,_xlfn.SWITCH(X11,0,IF(S11<=O11,1,0),1,IF(S11<=P11,1,0),2,IF(S11<=Q11,1,0),3,IF(S11<=R11,1,0)),0)} -> 0
C12: Configuration | D12: 0.15 | E12: How are configuration changes executed? | F12: ='Change Management_Orange'!J10 -> 3 | G12: ='Change Management_Orange'!K10 -> 2 | H12: ='Change Management_Orange'!L10 -> 1 | I12: ='Change Management_Orange'!M10 -> 0 | J12: ='Change Management_Orange'!N10 -> A | K12: =IF(J12="A",F12,IF(J12="B",G12,IF(J12="C",H12,IF(J12="D",I12)))) -> 3 | L12: =IF(AND(K12=3,AVERAGE($K$4,$K$6,$K$7,$K$8)>3),AVERAGE($K$4,$K$6,$K$7,$K$8),K12) -> 3 | N12: C | O12: B | P12: A | Q12: A | R12: A | S12: =J12 -> A | T12: =IF(S12=0,0,IF(S12<=O12,1,0)) -> 1 | U12: =IF(S12=0,0,IF(S12<=P12,1,0)) -> 1 | V12: =IF(S12=0,0,IF(S12<=Q12,1,0)) -> 1 | W12: =IF(S12=0,0,IF(S12<=R12,1,0)) -> 1 | Y12: {=_xlfn.SWITCH(X12,0,IF(O12<N12,1,0),1,IF(P12<O12,1,0),2,IF(Q12<P12,1,0),3,IF(R12<Q12,1,0),4,0)} -> 1 | Z12: {=IF(Y12>0,_xlfn.SWITCH(X12,0,IF(S12<=O12,1,0),1,IF(S12<=P12,1,0),2,IF(S12<=Q12,1,0),3,IF(S12<=R12,1,0)),0)} -> 1
D13: =SUM(D4:D12) -> 1
B14: Note: Automatic formula calculation. Do not modify it.

Sheet Change Management-tracking_Oran
A1: High-Value Scenario | B1: Cognitive Activity (IAADE) | C1: Service Capability | D1: Weight | E1: Question | F1: Option A | G1: Option B | H1: Option C | I1: Option D | J1: Option A | K1: Option B | L1: Option C | M1: Option D | N1: Answer | O1: Interpretating on question | P1: Understanding of selecting the option
A2: Change management | B2: Intent | C2: Intent-driven | D2: 0.1 | E2: How are change management activities (any kind of configuration change over the network elements, software upgrades) defined? Intents input can be: new service requirements, resolution of network incident, network performance optimization… | F2: Change management is requested through intent-based (declarative) APIs (TMF921 intent APIs when defined and specific intent APIs when not defined by TMF), which are able to translate high-level intents into task targets and policies and specific configurations of final network equipment. As an intent, there's a continuous reconciliation to ensure that the intent is always respected. | G2: Change management is requested through intent-based (declarative) APIs, which are able to translate high-level intents into task targets and policies and specific configurations of final network equipment. There's no continuous control to ensure the intent is respected. | H2: Change management activities are defined in imperative way through workflows and/or basic "templates". | I2: Neither intent nor imperative APIs are used. Every change management task requires a specific design ( ‘Low Level Design) | J2: =Scoring_Orange!F4 -> 4 | K2: =Scoring_Orange!G4 -> 3 | L2: =Scoring_Orange!H4 -> 1 | M2: =Scoring_Orange!I4 -> 0 | N2: A
B3: Awareness | C3: Data collection | D3: 0.05 | E3: How are the inputs for the change management process collected? | F3: All the inputs are automatically collected (from OSS tools, inventories, network reconciliation process, supplier artifacts repositories…) | G3: Some inputs are collected automatically but others require human intervention. | H3: The inputs require manual selection from a portal or similar tool (simplifying data acquisition) | I3: Fully manual acquisition process of the inputs | J3: =Scoring_Orange!F5 -> 3 | K3: =Scoring_Orange!G5 -> 2 | L3: =Scoring_Orange!H5 -> 1 | M3: =Scoring_Orange!I5 -> 0 | N3: A
B4: Analysis | C4: Analysis | D4: 0.1 | E4: How collected information is analyzed and transform it into knowledge (the input for the decision phase)? | F4: Total. Information is translated into knowledge thanks to dynamic (intelligent) rules | G4: Partially. The system can automatically make an analysis of the situation based on statically defined rules | H4: No. Fully human-driven analysis process | J4: =Scoring_Orange!F6 -> 4 | K4: =Scoring_Orange!G6 -> 3 | L4: =Scoring_Orange!H6 -> 0 | M4: =Scoring_Orange!I6 -> 0 | N4: A
C5: Prediction | D5: 0.15 | E5: Which level of prediction capabilities does the change management process support? For instance, for scenarios which can require such capabilities are capacity upgrade (to ensure the Hardware acquisition process is launched in advanced) | F5: Total. Based on intents, The system is able to inform of future events (based on dynamic / intelligent rules) to ensure that actions (mainly non-automated ones) can be executed before they are needed. | G5: Partial. The system can identify potential future change management events based on manually defined (static) rules | H5: None. Prediction of future change management events must be human-driven | J5: =Scoring_Orange!F7 -> 4 | K5: =Scoring_Orange!G7 -> 3 | L5: =Scoring_Orange!H7 -> 0 | M5: =Scoring_Orange!I7 -> 0 | N5: A
B6: Decision | C6: Solution evaluation and decision-making | D6: 0.15 | E6: Which level of self-evaluation and self-decision is supported by the change management process? | F6: Total. The system automatically evaluates and determines the optimal action to fulfill the intent, based on dynamic rules. | G6: Partial. The system automatically evaluates and decides the action to execute based on static policy rules. | H6: None. The optimal solution needs to be manually evaluated and decided. | J6: =Scoring_Orange!F8 -> 4 | K6: =Scoring_Orange!G8 -> 3 | L6: =Scoring_Orange!H8 -> 1 | M6: =Scoring_Orange!I8 -> 0 | N6: B
B7: Execution | C7: Testing | D7: 0.1 | E7: How are the executions of the change management process tested to ensure no problem has arisen due to the change? | F7: Total. Changes are tested automatically during the change execution. If any issue is detected (with the service or with any other related service that could be impacted by the change), an automated roll-back is executed | G7: Partial. Some automated tests are available and are automatically triggered during the execution. If an error is detected, automated roll-back is executed. Other tests remain to be human-triggered | H7: Partial. Only some automated tests are available but need to be triggered by human operator to check the execution result. No automated roll-back | I7: Manual tests are executed to check the result of the change | J7: =Scoring_Orange!F9 -> 3 | K7: =Scoring_Orange!G9 -> 2 | L7: =Scoring_Orange!H9 -> 1 | M7: =Scoring_Orange!I9 -> 0 | N7: C
C8: Hardware | D8: 0.05 | E8: How is new hardware integrated and configured? | F8: Total. Hardware installation is done through a zero-touch process (fully plug and play) | G8: Partial. Some of the process is automated but not zero-touch level is reached. | H8: None. Full manual process. | J8: =Scoring_Orange!F10 -> 2 | K8: =Scoring_Orange!G10 -> 1 | L8: =Scoring_Orange!H10 -> 0 | M8: =Scoring_Orange!I10 -> 0 | N8: C
C9: Software | D9: 0.15 | E9: How is software change management process executed? | F9: Fully automated. Software upgrade/update can be done continuously with no human intervention and none or limited service impact.* | G9: Partial. Software upgrade process is automated but in different steps that require human intervention to execute all the different steps. Some automation developments are intent-based; most of the automation are just simple scripts | H9: Some automation tools, and some software change/Release done remotely without any physical presence on the site | I9: Full manual process, with possible vendor tool assistance. | J9: =Scoring_Orange!F11 -> 3 | K9: =Scoring_Orange!G11 -> 2 | L9: =Scoring_Orange!H11 -> 1 | M9: =Scoring_Orange!I11 -> 0 | N9: B
